/bin/bash: /afs/ifh.de/user/t/tuccia/.profile: Permission denied
/bin/bash: /afs/ifh.de/user/t/tuccia/.profile: Permission denied
/bin/bash: /afs/ifh.de/user/t/tuccia/.profile: Permission denied
/bin/bash: /afs/ifh.de/user/t/tuccia/.profile: Permission denied
/bin/bash: /afs/ifh.de/user/t/tuccia/.profile: Permission denied
/bin/bash: /afs/ifh.de/user/t/tuccia/.profile: Permission denied
/lustre/fs24/group/cqta/atucci/environment/lib64/python3.9/site-packages/networkx/utils/backends.py:135: RuntimeWarning: networkx backend defined more than once: nx-loopback
  backends.update(_get_backends("networkx.backends"))
/lustre/fs24/group/cqta/atucci/environment/lib64/python3.9/site-packages/networkx/utils/backends.py:135: RuntimeWarning: networkx backend defined more than once: nx-loopback
  backends.update(_get_backends("networkx.backends"))
/lustre/fs24/group/cqta/atucci/environment/lib64/python3.9/site-packages/networkx/utils/backends.py:135: RuntimeWarning: networkx backend defined more than once: nx-loopback
  backends.update(_get_backends("networkx.backends"))
/lustre/fs24/group/cqta/atucci/environment/lib64/python3.9/site-packages/networkx/utils/backends.py:135: RuntimeWarning: networkx backend defined more than once: nx-loopback
  backends.update(_get_backends("networkx.backends"))
/lustre/fs24/group/cqta/atucci/environment/lib64/python3.9/site-packages/networkx/utils/backends.py:135: RuntimeWarning: networkx backend defined more than once: nx-loopback
  backends.update(_get_backends("networkx.backends"))
/lustre/fs24/group/cqta/atucci/environment/lib64/python3.9/site-packages/networkx/utils/backends.py:135: RuntimeWarning: networkx backend defined more than once: nx-loopback
  backends.update(_get_backends("networkx.backends"))
Traceback (most recent call last):
  File "/lustre/fs24/group/cqta/atucci/Random_cubo/Random_cubo_codes/run_qubo_iterate_adap_sorting_entropy.py", line 253, in <module>
    main()
  File "/lustre/fs24/group/cqta/atucci/Random_cubo/Random_cubo_codes/run_qubo_iterate_adap_sorting_entropy.py", line 118, in main
    with open(instance_dir + '/QUBO_' + str(n_qubits ) + 'V_'+ 'r_'+ str(r)+ '.gpickle', 'rb') as f:
FileNotFoundError: [Errno 2] No such file or directory: '../instances/complete/N_22/QUBO_22V_r_397.gpickle'
/bin/bash: /afs/ifh.de/user/t/tuccia/.profile: Permission denied
/lustre/fs24/group/cqta/atucci/environment/lib64/python3.9/site-packages/networkx/utils/backends.py:135: RuntimeWarning: networkx backend defined more than once: nx-loopback
  backends.update(_get_backends("networkx.backends"))
/bin/bash: /afs/ifh.de/user/t/tuccia/.profile: Permission denied
/lustre/fs24/group/cqta/atucci/environment/lib64/python3.9/site-packages/networkx/utils/backends.py:135: RuntimeWarning: networkx backend defined more than once: nx-loopback
  backends.update(_get_backends("networkx.backends"))
/bin/bash: /afs/ifh.de/user/t/tuccia/.profile: Permission denied
/lustre/fs24/group/cqta/atucci/environment/lib64/python3.9/site-packages/networkx/utils/backends.py:135: RuntimeWarning: networkx backend defined more than once: nx-loopback
  backends.update(_get_backends("networkx.backends"))
/lustre/fs24/group/cqta/atucci/environment/lib64/python3.9/site-packages/networkx/utils/backends.py:135: RuntimeWarning: networkx backend defined more than once: nx-loopback
  backends.update(_get_backends("networkx.backends"))
/bin/bash: /afs/ifh.de/user/t/tuccia/.profile: Permission denied
/lustre/fs24/group/cqta/atucci/environment/lib64/python3.9/site-packages/networkx/utils/backends.py:135: RuntimeWarning: networkx backend defined more than once: nx-loopback
  backends.update(_get_backends("networkx.backends"))
/bin/bash: /afs/ifh.de/user/t/tuccia/.profile: Permission denied
/lustre/fs24/group/cqta/atucci/environment/lib64/python3.9/site-packages/networkx/utils/backends.py:135: RuntimeWarning: networkx backend defined more than once: nx-loopback
  backends.update(_get_backends("networkx.backends"))
/bin/bash: /afs/ifh.de/user/t/tuccia/.profile: Permission denied
/lustre/fs24/group/cqta/atucci/environment/lib64/python3.9/site-packages/networkx/utils/backends.py:135: RuntimeWarning: networkx backend defined more than once: nx-loopback
  backends.update(_get_backends("networkx.backends"))
/bin/bash: /afs/ifh.de/user/t/tuccia/.profile: Permission denied
/lustre/fs24/group/cqta/atucci/environment/lib64/python3.9/site-packages/networkx/utils/backends.py:135: RuntimeWarning: networkx backend defined more than once: nx-loopback
  backends.update(_get_backends("networkx.backends"))
/bin/bash: /afs/ifh.de/user/t/tuccia/.profile: Permission denied
/lustre/fs24/group/cqta/atucci/environment/lib64/python3.9/site-packages/networkx/utils/backends.py:135: RuntimeWarning: networkx backend defined more than once: nx-loopback
  backends.update(_get_backends("networkx.backends"))
Traceback (most recent call last):
  File "/lustre/fs24/group/cqta/atucci/Random_cubo/Random_cubo_codes/run_qubo_iterate_adap_sorting_entropy.py", line 253, in <module>
    main()
  File "/lustre/fs24/group/cqta/atucci/Random_cubo/Random_cubo_codes/run_qubo_iterate_adap_sorting_entropy.py", line 118, in main
    with open(instance_dir + '/QUBO_' + str(n_qubits ) + 'V_'+ 'r_'+ str(r)+ '.gpickle', 'rb') as f:
FileNotFoundError: [Errno 2] No such file or directory: '../instances/complete/N_22/QUBO_22V_r_398.gpickle'
/bin/bash: /afs/ifh.de/user/t/tuccia/.profile: Permission denied
/lustre/fs24/group/cqta/atucci/environment/lib64/python3.9/site-packages/networkx/utils/backends.py:135: RuntimeWarning: networkx backend defined more than once: nx-loopback
  backends.update(_get_backends("networkx.backends"))
/bin/bash: /afs/ifh.de/user/t/tuccia/.profile: Permission denied
/lustre/fs24/group/cqta/atucci/environment/lib64/python3.9/site-packages/networkx/utils/backends.py:135: RuntimeWarning: networkx backend defined more than once: nx-loopback
  backends.update(_get_backends("networkx.backends"))
/bin/bash: /afs/ifh.de/user/t/tuccia/.profile: Permission denied
/lustre/fs24/group/cqta/atucci/environment/lib64/python3.9/site-packages/networkx/utils/backends.py:135: RuntimeWarning: networkx backend defined more than once: nx-loopback
  backends.update(_get_backends("networkx.backends"))
Traceback (most recent call last):
  File "/lustre/fs24/group/cqta/atucci/Random_cubo/Random_cubo_codes/run_qubo_iterate_adap_sorting_entropy.py", line 253, in <module>
    main()
  File "/lustre/fs24/group/cqta/atucci/Random_cubo/Random_cubo_codes/run_qubo_iterate_adap_sorting_entropy.py", line 118, in main
    with open(instance_dir + '/QUBO_' + str(n_qubits ) + 'V_'+ 'r_'+ str(r)+ '.gpickle', 'rb') as f:
FileNotFoundError: [Errno 2] No such file or directory: '../instances/complete/N_22/QUBO_22V_r_399.gpickle'
/lustre/fs24/group/cqta/atucci/environment/lib64/python3.9/site-packages/networkx/utils/backends.py:135: RuntimeWarning: networkx backend defined more than once: nx-loopback
  backends.update(_get_backends("networkx.backends"))
Traceback (most recent call last):
  File "/lustre/fs24/group/cqta/atucci/Random_cubo/Random_cubo_codes/run_qubo_iterate_adap_sorting_entropy.py", line 253, in <module>
    main()
  File "/lustre/fs24/group/cqta/atucci/Random_cubo/Random_cubo_codes/run_qubo_iterate_adap_sorting_entropy.py", line 118, in main
    with open(instance_dir + '/QUBO_' + str(n_qubits ) + 'V_'+ 'r_'+ str(r)+ '.gpickle', 'rb') as f:
FileNotFoundError: [Errno 2] No such file or directory: '../instances/complete/N_22/QUBO_22V_r_391.gpickle'
