/bin/bash: /afs/ifh.de/user/t/tuccia/.profile: Permission denied
/bin/bash: /afs/ifh.de/user/t/tuccia/.profile: Permission denied
/bin/bash: /afs/ifh.de/user/t/tuccia/.profile: Permission denied
/lustre/fs24/group/cqta/atucci/environment/lib64/python3.9/site-packages/networkx/utils/backends.py:135: RuntimeWarning: networkx backend defined more than once: nx-loopback
  backends.update(_get_backends("networkx.backends"))
/lustre/fs24/group/cqta/atucci/environment/lib64/python3.9/site-packages/networkx/utils/backends.py:135: RuntimeWarning: networkx backend defined more than once: nx-loopback
  backends.update(_get_backends("networkx.backends"))
/lustre/fs24/group/cqta/atucci/environment/lib64/python3.9/site-packages/networkx/utils/backends.py:135: RuntimeWarning: networkx backend defined more than once: nx-loopback
  backends.update(_get_backends("networkx.backends"))
/bin/bash: /afs/ifh.de/user/t/tuccia/.profile: Permission denied
/bin/bash: /afs/ifh.de/user/t/tuccia/.profile: Permission denied
/bin/bash: /afs/ifh.de/user/t/tuccia/.profile: Permission denied
/bin/bash: /afs/ifh.de/user/t/tuccia/.profile: Permission denied
/bin/bash: /afs/ifh.de/user/t/tuccia/.profile: Permission denied
/lustre/fs24/group/cqta/atucci/environment/lib64/python3.9/site-packages/networkx/utils/backends.py:135: RuntimeWarning: networkx backend defined more than once: nx-loopback
  backends.update(_get_backends("networkx.backends"))
/lustre/fs24/group/cqta/atucci/environment/lib64/python3.9/site-packages/networkx/utils/backends.py:135: RuntimeWarning: networkx backend defined more than once: nx-loopback
  backends.update(_get_backends("networkx.backends"))
/lustre/fs24/group/cqta/atucci/environment/lib64/python3.9/site-packages/networkx/utils/backends.py:135: RuntimeWarning: networkx backend defined more than once: nx-loopback
  backends.update(_get_backends("networkx.backends"))
Traceback (most recent call last):
  File "/lustre/fs24/group/cqta/atucci/Random_cubo/Random_cubo_codes/run_qubo_iterate_adap_sorting_entropy.py", line 253, in <module>
    main()
  File "/lustre/fs24/group/cqta/atucci/Random_cubo/Random_cubo_codes/run_qubo_iterate_adap_sorting_entropy.py", line 118, in main
    with open(instance_dir + '/QUBO_' + str(n_qubits ) + 'V_'+ 'r_'+ str(r)+ '.gpickle', 'rb') as f:
FileNotFoundError: [Errno 2] No such file or directory: '../instances/complete/N_18/QUBO_18V_r_361.gpickle'
Traceback (most recent call last):
  File "/lustre/fs24/group/cqta/atucci/Random_cubo/Random_cubo_codes/run_qubo_iterate_adap_sorting_entropy.py", line 253, in <module>
    main()
  File "/lustre/fs24/group/cqta/atucci/Random_cubo/Random_cubo_codes/run_qubo_iterate_adap_sorting_entropy.py", line 118, in main
    with open(instance_dir + '/QUBO_' + str(n_qubits ) + 'V_'+ 'r_'+ str(r)+ '.gpickle', 'rb') as f:
FileNotFoundError: [Errno 2] No such file or directory: '../instances/complete/N_18/QUBO_18V_r_359.gpickle'
Traceback (most recent call last):
  File "/lustre/fs24/group/cqta/atucci/Random_cubo/Random_cubo_codes/run_qubo_iterate_adap_sorting_entropy.py", line 253, in <module>
    main()
  File "/lustre/fs24/group/cqta/atucci/Random_cubo/Random_cubo_codes/run_qubo_iterate_adap_sorting_entropy.py", line 118, in main
    with open(instance_dir + '/QUBO_' + str(n_qubits ) + 'V_'+ 'r_'+ str(r)+ '.gpickle', 'rb') as f:
FileNotFoundError: [Errno 2] No such file or directory: '../instances/complete/N_18/QUBO_18V_r_360.gpickle'
/bin/bash: /afs/ifh.de/user/t/tuccia/.profile: Permission denied
/bin/bash: /afs/ifh.de/user/t/tuccia/.profile: Permission denied
/bin/bash: /afs/ifh.de/user/t/tuccia/.profile: Permission denied
/bin/bash: /afs/ifh.de/user/t/tuccia/.profile: Permission denied
Traceback (most recent call last):
  File "/lustre/fs24/group/cqta/atucci/Random_cubo/Random_cubo_codes/run_qubo_iterate_adap_sorting_entropy.py", line 253, in <module>
    main()
  File "/lustre/fs24/group/cqta/atucci/Random_cubo/Random_cubo_codes/run_qubo_iterate_adap_sorting_entropy.py", line 118, in main
    with open(instance_dir + '/QUBO_' + str(n_qubits ) + 'V_'+ 'r_'+ str(r)+ '.gpickle', 'rb') as f:
FileNotFoundError: [Errno 2] No such file or directory: '../instances/complete/N_18/QUBO_18V_r_362.gpickle'
/lustre/fs24/group/cqta/atucci/environment/lib64/python3.9/site-packages/networkx/utils/backends.py:135: RuntimeWarning: networkx backend defined more than once: nx-loopback
  backends.update(_get_backends("networkx.backends"))
Traceback (most recent call last):
  File "/lustre/fs24/group/cqta/atucci/Random_cubo/Random_cubo_codes/run_qubo_iterate_adap_sorting_entropy.py", line 253, in <module>
    main()
  File "/lustre/fs24/group/cqta/atucci/Random_cubo/Random_cubo_codes/run_qubo_iterate_adap_sorting_entropy.py", line 118, in main
    with open(instance_dir + '/QUBO_' + str(n_qubits ) + 'V_'+ 'r_'+ str(r)+ '.gpickle', 'rb') as f:
FileNotFoundError: [Errno 2] No such file or directory: '../instances/complete/N_18/QUBO_18V_r_363.gpickle'
Traceback (most recent call last):
  File "/lustre/fs24/group/cqta/atucci/Random_cubo/Random_cubo_codes/run_qubo_iterate_adap_sorting_entropy.py", line 253, in <module>
    main()
  File "/lustre/fs24/group/cqta/atucci/Random_cubo/Random_cubo_codes/run_qubo_iterate_adap_sorting_entropy.py", line 118, in main
    with open(instance_dir + '/QUBO_' + str(n_qubits ) + 'V_'+ 'r_'+ str(r)+ '.gpickle', 'rb') as f:
FileNotFoundError: [Errno 2] No such file or directory: '../instances/complete/N_18/QUBO_18V_r_364.gpickle'
Traceback (most recent call last):
  File "/lustre/fs24/group/cqta/atucci/Random_cubo/Random_cubo_codes/run_qubo_iterate_adap_sorting_entropy.py", line 253, in <module>
    main()
  File "/lustre/fs24/group/cqta/atucci/Random_cubo/Random_cubo_codes/run_qubo_iterate_adap_sorting_entropy.py", line 118, in main
    with open(instance_dir + '/QUBO_' + str(n_qubits ) + 'V_'+ 'r_'+ str(r)+ '.gpickle', 'rb') as f:
FileNotFoundError: [Errno 2] No such file or directory: '../instances/complete/N_18/QUBO_18V_r_365.gpickle'
/bin/bash: /afs/ifh.de/user/t/tuccia/.profile: Permission denied
/bin/bash: /afs/ifh.de/user/t/tuccia/.profile: Permission denied
/bin/bash: /afs/ifh.de/user/t/tuccia/.profile: Permission denied
/bin/bash: /afs/ifh.de/user/t/tuccia/.profile: Permission denied
/lustre/fs24/group/cqta/atucci/environment/lib64/python3.9/site-packages/networkx/utils/backends.py:135: RuntimeWarning: networkx backend defined more than once: nx-loopback
  backends.update(_get_backends("networkx.backends"))
/bin/bash: /afs/ifh.de/user/t/tuccia/.profile: Permission denied
/bin/bash: /afs/ifh.de/user/t/tuccia/.profile: Permission denied
/lustre/fs24/group/cqta/atucci/environment/lib64/python3.9/site-packages/networkx/utils/backends.py:135: RuntimeWarning: networkx backend defined more than once: nx-loopback
  backends.update(_get_backends("networkx.backends"))
/lustre/fs24/group/cqta/atucci/environment/lib64/python3.9/site-packages/networkx/utils/backends.py:135: RuntimeWarning: networkx backend defined more than once: nx-loopback
  backends.update(_get_backends("networkx.backends"))
/lustre/fs24/group/cqta/atucci/environment/lib64/python3.9/site-packages/networkx/utils/backends.py:135: RuntimeWarning: networkx backend defined more than once: nx-loopback
  backends.update(_get_backends("networkx.backends"))
/bin/bash: /afs/ifh.de/user/t/tuccia/.profile: Permission denied
/bin/bash: /afs/ifh.de/user/t/tuccia/.profile: Permission denied
/lustre/fs24/group/cqta/atucci/environment/lib64/python3.9/site-packages/networkx/utils/backends.py:135: RuntimeWarning: networkx backend defined more than once: nx-loopback
  backends.update(_get_backends("networkx.backends"))
/lustre/fs24/group/cqta/atucci/environment/lib64/python3.9/site-packages/networkx/utils/backends.py:135: RuntimeWarning: networkx backend defined more than once: nx-loopback
  backends.update(_get_backends("networkx.backends"))
/lustre/fs24/group/cqta/atucci/environment/lib64/python3.9/site-packages/networkx/utils/backends.py:135: RuntimeWarning: networkx backend defined more than once: nx-loopback
  backends.update(_get_backends("networkx.backends"))
Traceback (most recent call last):
  File "/lustre/fs24/group/cqta/atucci/Random_cubo/Random_cubo_codes/run_qubo_iterate_adap_sorting_entropy.py", line 253, in <module>
    main()
  File "/lustre/fs24/group/cqta/atucci/Random_cubo/Random_cubo_codes/run_qubo_iterate_adap_sorting_entropy.py", line 118, in main
    with open(instance_dir + '/QUBO_' + str(n_qubits ) + 'V_'+ 'r_'+ str(r)+ '.gpickle', 'rb') as f:
FileNotFoundError: [Errno 2] No such file or directory: '../instances/complete/N_18/QUBO_18V_r_375.gpickle'
/lustre/fs24/group/cqta/atucci/environment/lib64/python3.9/site-packages/networkx/utils/backends.py:135: RuntimeWarning: networkx backend defined more than once: nx-loopback
  backends.update(_get_backends("networkx.backends"))
Traceback (most recent call last):
  File "/lustre/fs24/group/cqta/atucci/Random_cubo/Random_cubo_codes/run_qubo_iterate_adap_sorting_entropy.py", line 253, in <module>
    main()
  File "/lustre/fs24/group/cqta/atucci/Random_cubo/Random_cubo_codes/run_qubo_iterate_adap_sorting_entropy.py", line 118, in main
    with open(instance_dir + '/QUBO_' + str(n_qubits ) + 'V_'+ 'r_'+ str(r)+ '.gpickle', 'rb') as f:
FileNotFoundError: [Errno 2] No such file or directory: '../instances/complete/N_18/QUBO_18V_r_315.gpickle'
Traceback (most recent call last):
  File "/lustre/fs24/group/cqta/atucci/Random_cubo/Random_cubo_codes/run_qubo_iterate_adap_sorting_entropy.py", line 253, in <module>
    main()
  File "/lustre/fs24/group/cqta/atucci/Random_cubo/Random_cubo_codes/run_qubo_iterate_adap_sorting_entropy.py", line 118, in main
    with open(instance_dir + '/QUBO_' + str(n_qubits ) + 'V_'+ 'r_'+ str(r)+ '.gpickle', 'rb') as f:
FileNotFoundError: [Errno 2] No such file or directory: '../instances/complete/N_18/QUBO_18V_r_367.gpickle'
/bin/bash: /afs/ifh.de/user/t/tuccia/.profile: Permission denied
Traceback (most recent call last):
  File "/lustre/fs24/group/cqta/atucci/Random_cubo/Random_cubo_codes/run_qubo_iterate_adap_sorting_entropy.py", line 253, in <module>
    main()
  File "/lustre/fs24/group/cqta/atucci/Random_cubo/Random_cubo_codes/run_qubo_iterate_adap_sorting_entropy.py", line 118, in main
    with open(instance_dir + '/QUBO_' + str(n_qubits ) + 'V_'+ 'r_'+ str(r)+ '.gpickle', 'rb') as f:
FileNotFoundError: [Errno 2] No such file or directory: '../instances/complete/N_18/QUBO_18V_r_377.gpickle'
Traceback (most recent call last):
  File "/lustre/fs24/group/cqta/atucci/Random_cubo/Random_cubo_codes/run_qubo_iterate_adap_sorting_entropy.py", line 253, in <module>
    main()
  File "/lustre/fs24/group/cqta/atucci/Random_cubo/Random_cubo_codes/run_qubo_iterate_adap_sorting_entropy.py", line 118, in main
    with open(instance_dir + '/QUBO_' + str(n_qubits ) + 'V_'+ 'r_'+ str(r)+ '.gpickle', 'rb') as f:
FileNotFoundError: [Errno 2] No such file or directory: '../instances/complete/N_18/QUBO_18V_r_368.gpickle'
/lustre/fs24/group/cqta/atucci/environment/lib64/python3.9/site-packages/networkx/utils/backends.py:135: RuntimeWarning: networkx backend defined more than once: nx-loopback
  backends.update(_get_backends("networkx.backends"))
Traceback (most recent call last):
  File "/lustre/fs24/group/cqta/atucci/Random_cubo/Random_cubo_codes/run_qubo_iterate_adap_sorting_entropy.py", line 253, in <module>
    main()
  File "/lustre/fs24/group/cqta/atucci/Random_cubo/Random_cubo_codes/run_qubo_iterate_adap_sorting_entropy.py", line 118, in main
    with open(instance_dir + '/QUBO_' + str(n_qubits ) + 'V_'+ 'r_'+ str(r)+ '.gpickle', 'rb') as f:
FileNotFoundError: [Errno 2] No such file or directory: '../instances/complete/N_18/QUBO_18V_r_390.gpickle'
Traceback (most recent call last):
  File "/lustre/fs24/group/cqta/atucci/Random_cubo/Random_cubo_codes/run_qubo_iterate_adap_sorting_entropy.py", line 253, in <module>
    main()
  File "/lustre/fs24/group/cqta/atucci/Random_cubo/Random_cubo_codes/run_qubo_iterate_adap_sorting_entropy.py", line 118, in main
    with open(instance_dir + '/QUBO_' + str(n_qubits ) + 'V_'+ 'r_'+ str(r)+ '.gpickle', 'rb') as f:
FileNotFoundError: [Errno 2] No such file or directory: '../instances/complete/N_18/QUBO_18V_r_341.gpickle'
/lustre/fs24/group/cqta/atucci/environment/lib64/python3.9/site-packages/networkx/utils/backends.py:135: RuntimeWarning: networkx backend defined more than once: nx-loopback
  backends.update(_get_backends("networkx.backends"))
/lustre/fs24/group/cqta/atucci/environment/lib64/python3.9/site-packages/networkx/utils/backends.py:135: RuntimeWarning: networkx backend defined more than once: nx-loopback
  backends.update(_get_backends("networkx.backends"))
/lustre/fs24/group/cqta/atucci/environment/lib64/python3.9/site-packages/networkx/utils/backends.py:135: RuntimeWarning: networkx backend defined more than once: nx-loopback
  backends.update(_get_backends("networkx.backends"))
Traceback (most recent call last):
  File "/lustre/fs24/group/cqta/atucci/Random_cubo/Random_cubo_codes/run_qubo_iterate_adap_sorting_entropy.py", line 253, in <module>
    main()
  File "/lustre/fs24/group/cqta/atucci/Random_cubo/Random_cubo_codes/run_qubo_iterate_adap_sorting_entropy.py", line 118, in main
    with open(instance_dir + '/QUBO_' + str(n_qubits ) + 'V_'+ 'r_'+ str(r)+ '.gpickle', 'rb') as f:
FileNotFoundError: [Errno 2] No such file or directory: '../instances/complete/N_18/QUBO_18V_r_372.gpickle'
Traceback (most recent call last):
  File "/lustre/fs24/group/cqta/atucci/Random_cubo/Random_cubo_codes/run_qubo_iterate_adap_sorting_entropy.py", line 253, in <module>
    main()
  File "/lustre/fs24/group/cqta/atucci/Random_cubo/Random_cubo_codes/run_qubo_iterate_adap_sorting_entropy.py", line 118, in main
    with open(instance_dir + '/QUBO_' + str(n_qubits ) + 'V_'+ 'r_'+ str(r)+ '.gpickle', 'rb') as f:
FileNotFoundError: [Errno 2] No such file or directory: '../instances/complete/N_18/QUBO_18V_r_376.gpickle'
/bin/bash: /afs/ifh.de/user/t/tuccia/.profile: Permission denied
/bin/bash: /afs/ifh.de/user/t/tuccia/.profile: Permission denied
/bin/bash: /afs/ifh.de/user/t/tuccia/.profile: Permission denied
/lustre/fs24/group/cqta/atucci/environment/lib64/python3.9/site-packages/networkx/utils/backends.py:135: RuntimeWarning: networkx backend defined more than once: nx-loopback
  backends.update(_get_backends("networkx.backends"))
/bin/bash: /afs/ifh.de/user/t/tuccia/.profile: Permission denied
/bin/bash: /afs/ifh.de/user/t/tuccia/.profile: Permission denied
/lustre/fs24/group/cqta/atucci/environment/lib64/python3.9/site-packages/networkx/utils/backends.py:135: RuntimeWarning: networkx backend defined more than once: nx-loopback
  backends.update(_get_backends("networkx.backends"))
/lustre/fs24/group/cqta/atucci/environment/lib64/python3.9/site-packages/networkx/utils/backends.py:135: RuntimeWarning: networkx backend defined more than once: nx-loopback
  backends.update(_get_backends("networkx.backends"))
/bin/bash: /afs/ifh.de/user/t/tuccia/.profile: Permission denied
/bin/bash: /afs/ifh.de/user/t/tuccia/.profile: Permission denied
/lustre/fs24/group/cqta/atucci/environment/lib64/python3.9/site-packages/networkx/utils/backends.py:135: RuntimeWarning: networkx backend defined more than once: nx-loopback
  backends.update(_get_backends("networkx.backends"))
/lustre/fs24/group/cqta/atucci/environment/lib64/python3.9/site-packages/networkx/utils/backends.py:135: RuntimeWarning: networkx backend defined more than once: nx-loopback
  backends.update(_get_backends("networkx.backends"))
/lustre/fs24/group/cqta/atucci/environment/lib64/python3.9/site-packages/networkx/utils/backends.py:135: RuntimeWarning: networkx backend defined more than once: nx-loopback
  backends.update(_get_backends("networkx.backends"))
Traceback (most recent call last):
  File "/lustre/fs24/group/cqta/atucci/Random_cubo/Random_cubo_codes/run_qubo_iterate_adap_sorting_entropy.py", line 253, in <module>
    main()
  File "/lustre/fs24/group/cqta/atucci/Random_cubo/Random_cubo_codes/run_qubo_iterate_adap_sorting_entropy.py", line 118, in main
    with open(instance_dir + '/QUBO_' + str(n_qubits ) + 'V_'+ 'r_'+ str(r)+ '.gpickle', 'rb') as f:
FileNotFoundError: [Errno 2] No such file or directory: '../instances/complete/N_18/QUBO_18V_r_374.gpickle'
/lustre/fs24/group/cqta/atucci/environment/lib64/python3.9/site-packages/networkx/utils/backends.py:135: RuntimeWarning: networkx backend defined more than once: nx-loopback
  backends.update(_get_backends("networkx.backends"))
Traceback (most recent call last):
  File "/lustre/fs24/group/cqta/atucci/Random_cubo/Random_cubo_codes/run_qubo_iterate_adap_sorting_entropy.py", line 253, in <module>
    main()
  File "/lustre/fs24/group/cqta/atucci/Random_cubo/Random_cubo_codes/run_qubo_iterate_adap_sorting_entropy.py", line 118, in main
    with open(instance_dir + '/QUBO_' + str(n_qubits ) + 'V_'+ 'r_'+ str(r)+ '.gpickle', 'rb') as f:
FileNotFoundError: [Errno 2] No such file or directory: '../instances/complete/N_18/QUBO_18V_r_383.gpickle'
Traceback (most recent call last):
  File "/lustre/fs24/group/cqta/atucci/Random_cubo/Random_cubo_codes/run_qubo_iterate_adap_sorting_entropy.py", line 253, in <module>
    main()
  File "/lustre/fs24/group/cqta/atucci/Random_cubo/Random_cubo_codes/run_qubo_iterate_adap_sorting_entropy.py", line 118, in main
    with open(instance_dir + '/QUBO_' + str(n_qubits ) + 'V_'+ 'r_'+ str(r)+ '.gpickle', 'rb') as f:
FileNotFoundError: [Errno 2] No such file or directory: '../instances/complete/N_18/QUBO_18V_r_384.gpickle'
/bin/bash: /afs/ifh.de/user/t/tuccia/.profile: Permission denied
Traceback (most recent call last):
  File "/lustre/fs24/group/cqta/atucci/Random_cubo/Random_cubo_codes/run_qubo_iterate_adap_sorting_entropy.py", line 253, in <module>
    main()
  File "/lustre/fs24/group/cqta/atucci/Random_cubo/Random_cubo_codes/run_qubo_iterate_adap_sorting_entropy.py", line 118, in main
    with open(instance_dir + '/QUBO_' + str(n_qubits ) + 'V_'+ 'r_'+ str(r)+ '.gpickle', 'rb') as f:
FileNotFoundError: [Errno 2] No such file or directory: '../instances/complete/N_18/QUBO_18V_r_385.gpickle'
/lustre/fs24/group/cqta/atucci/environment/lib64/python3.9/site-packages/networkx/utils/backends.py:135: RuntimeWarning: networkx backend defined more than once: nx-loopback
  backends.update(_get_backends("networkx.backends"))
Traceback (most recent call last):
  File "/lustre/fs24/group/cqta/atucci/Random_cubo/Random_cubo_codes/run_qubo_iterate_adap_sorting_entropy.py", line 253, in <module>
    main()
  File "/lustre/fs24/group/cqta/atucci/Random_cubo/Random_cubo_codes/run_qubo_iterate_adap_sorting_entropy.py", line 118, in main
    with open(instance_dir + '/QUBO_' + str(n_qubits ) + 'V_'+ 'r_'+ str(r)+ '.gpickle', 'rb') as f:
FileNotFoundError: [Errno 2] No such file or directory: '../instances/complete/N_18/QUBO_18V_r_392.gpickle'
Traceback (most recent call last):
  File "/lustre/fs24/group/cqta/atucci/Random_cubo/Random_cubo_codes/run_qubo_iterate_adap_sorting_entropy.py", line 253, in <module>
    main()
  File "/lustre/fs24/group/cqta/atucci/Random_cubo/Random_cubo_codes/run_qubo_iterate_adap_sorting_entropy.py", line 118, in main
    with open(instance_dir + '/QUBO_' + str(n_qubits ) + 'V_'+ 'r_'+ str(r)+ '.gpickle', 'rb') as f:
FileNotFoundError: [Errno 2] No such file or directory: '../instances/complete/N_18/QUBO_18V_r_391.gpickle'
/lustre/fs24/group/cqta/atucci/environment/lib64/python3.9/site-packages/networkx/utils/backends.py:135: RuntimeWarning: networkx backend defined more than once: nx-loopback
  backends.update(_get_backends("networkx.backends"))
/lustre/fs24/group/cqta/atucci/environment/lib64/python3.9/site-packages/networkx/utils/backends.py:135: RuntimeWarning: networkx backend defined more than once: nx-loopback
  backends.update(_get_backends("networkx.backends"))
/lustre/fs24/group/cqta/atucci/environment/lib64/python3.9/site-packages/networkx/utils/backends.py:135: RuntimeWarning: networkx backend defined more than once: nx-loopback
  backends.update(_get_backends("networkx.backends"))
Traceback (most recent call last):
  File "/lustre/fs24/group/cqta/atucci/Random_cubo/Random_cubo_codes/run_qubo_iterate_adap_sorting_entropy.py", line 253, in <module>
    main()
  File "/lustre/fs24/group/cqta/atucci/Random_cubo/Random_cubo_codes/run_qubo_iterate_adap_sorting_entropy.py", line 118, in main
    with open(instance_dir + '/QUBO_' + str(n_qubits ) + 'V_'+ 'r_'+ str(r)+ '.gpickle', 'rb') as f:
FileNotFoundError: [Errno 2] No such file or directory: '../instances/complete/N_18/QUBO_18V_r_378.gpickle'
Traceback (most recent call last):
  File "/lustre/fs24/group/cqta/atucci/Random_cubo/Random_cubo_codes/run_qubo_iterate_adap_sorting_entropy.py", line 253, in <module>
    main()
  File "/lustre/fs24/group/cqta/atucci/Random_cubo/Random_cubo_codes/run_qubo_iterate_adap_sorting_entropy.py", line 118, in main
    with open(instance_dir + '/QUBO_' + str(n_qubits ) + 'V_'+ 'r_'+ str(r)+ '.gpickle', 'rb') as f:
FileNotFoundError: [Errno 2] No such file or directory: '../instances/complete/N_18/QUBO_18V_r_379.gpickle'
/bin/bash: /afs/ifh.de/user/t/tuccia/.profile: Permission denied
/bin/bash: /afs/ifh.de/user/t/tuccia/.profile: Permission denied
/bin/bash: /afs/ifh.de/user/t/tuccia/.profile: Permission denied
/lustre/fs24/group/cqta/atucci/environment/lib64/python3.9/site-packages/networkx/utils/backends.py:135: RuntimeWarning: networkx backend defined more than once: nx-loopback
  backends.update(_get_backends("networkx.backends"))
/bin/bash: /afs/ifh.de/user/t/tuccia/.profile: Permission denied
/lustre/fs24/group/cqta/atucci/environment/lib64/python3.9/site-packages/networkx/utils/backends.py:135: RuntimeWarning: networkx backend defined more than once: nx-loopback
  backends.update(_get_backends("networkx.backends"))
/lustre/fs24/group/cqta/atucci/environment/lib64/python3.9/site-packages/networkx/utils/backends.py:135: RuntimeWarning: networkx backend defined more than once: nx-loopback
  backends.update(_get_backends("networkx.backends"))
/bin/bash: /afs/ifh.de/user/t/tuccia/.profile: Permission denied
/bin/bash: /afs/ifh.de/user/t/tuccia/.profile: Permission denied
/lustre/fs24/group/cqta/atucci/environment/lib64/python3.9/site-packages/networkx/utils/backends.py:135: RuntimeWarning: networkx backend defined more than once: nx-loopback
  backends.update(_get_backends("networkx.backends"))
/lustre/fs24/group/cqta/atucci/environment/lib64/python3.9/site-packages/networkx/utils/backends.py:135: RuntimeWarning: networkx backend defined more than once: nx-loopback
  backends.update(_get_backends("networkx.backends"))
/lustre/fs24/group/cqta/atucci/environment/lib64/python3.9/site-packages/networkx/utils/backends.py:135: RuntimeWarning: networkx backend defined more than once: nx-loopback
  backends.update(_get_backends("networkx.backends"))
Traceback (most recent call last):
  File "/lustre/fs24/group/cqta/atucci/Random_cubo/Random_cubo_codes/run_qubo_iterate_adap_sorting_entropy.py", line 253, in <module>
    main()
  File "/lustre/fs24/group/cqta/atucci/Random_cubo/Random_cubo_codes/run_qubo_iterate_adap_sorting_entropy.py", line 118, in main
    with open(instance_dir + '/QUBO_' + str(n_qubits ) + 'V_'+ 'r_'+ str(r)+ '.gpickle', 'rb') as f:
FileNotFoundError: [Errno 2] No such file or directory: '../instances/complete/N_18/QUBO_18V_r_393.gpickle'
Traceback (most recent call last):
  File "/lustre/fs24/group/cqta/atucci/Random_cubo/Random_cubo_codes/run_qubo_iterate_adap_sorting_entropy.py", line 253, in <module>
    main()
  File "/lustre/fs24/group/cqta/atucci/Random_cubo/Random_cubo_codes/run_qubo_iterate_adap_sorting_entropy.py", line 118, in main
    with open(instance_dir + '/QUBO_' + str(n_qubits ) + 'V_'+ 'r_'+ str(r)+ '.gpickle', 'rb') as f:
FileNotFoundError: [Errno 2] No such file or directory: '../instances/complete/N_18/QUBO_18V_r_394.gpickle'
/bin/bash: /afs/ifh.de/user/t/tuccia/.profile: Permission denied
Traceback (most recent call last):
  File "/lustre/fs24/group/cqta/atucci/Random_cubo/Random_cubo_codes/run_qubo_iterate_adap_sorting_entropy.py", line 253, in <module>
    main()
  File "/lustre/fs24/group/cqta/atucci/Random_cubo/Random_cubo_codes/run_qubo_iterate_adap_sorting_entropy.py", line 118, in main
    with open(instance_dir + '/QUBO_' + str(n_qubits ) + 'V_'+ 'r_'+ str(r)+ '.gpickle', 'rb') as f:
FileNotFoundError: [Errno 2] No such file or directory: '../instances/complete/N_18/QUBO_18V_r_395.gpickle'
/lustre/fs24/group/cqta/atucci/environment/lib64/python3.9/site-packages/networkx/utils/backends.py:135: RuntimeWarning: networkx backend defined more than once: nx-loopback
  backends.update(_get_backends("networkx.backends"))
Traceback (most recent call last):
  File "/lustre/fs24/group/cqta/atucci/Random_cubo/Random_cubo_codes/run_qubo_iterate_adap_sorting_entropy.py", line 253, in <module>
    main()
  File "/lustre/fs24/group/cqta/atucci/Random_cubo/Random_cubo_codes/run_qubo_iterate_adap_sorting_entropy.py", line 118, in main
    with open(instance_dir + '/QUBO_' + str(n_qubits ) + 'V_'+ 'r_'+ str(r)+ '.gpickle', 'rb') as f:
FileNotFoundError: [Errno 2] No such file or directory: '../instances/complete/N_18/QUBO_18V_r_396.gpickle'
Traceback (most recent call last):
  File "/lustre/fs24/group/cqta/atucci/Random_cubo/Random_cubo_codes/run_qubo_iterate_adap_sorting_entropy.py", line 253, in <module>
    main()
  File "/lustre/fs24/group/cqta/atucci/Random_cubo/Random_cubo_codes/run_qubo_iterate_adap_sorting_entropy.py", line 118, in main
    with open(instance_dir + '/QUBO_' + str(n_qubits ) + 'V_'+ 'r_'+ str(r)+ '.gpickle', 'rb') as f:
FileNotFoundError: [Errno 2] No such file or directory: '../instances/complete/N_18/QUBO_18V_r_398.gpickle'
Traceback (most recent call last):
  File "/lustre/fs24/group/cqta/atucci/Random_cubo/Random_cubo_codes/run_qubo_iterate_adap_sorting_entropy.py", line 253, in <module>
    main()
  File "/lustre/fs24/group/cqta/atucci/Random_cubo/Random_cubo_codes/run_qubo_iterate_adap_sorting_entropy.py", line 118, in main
    with open(instance_dir + '/QUBO_' + str(n_qubits ) + 'V_'+ 'r_'+ str(r)+ '.gpickle', 'rb') as f:
FileNotFoundError: [Errno 2] No such file or directory: '../instances/complete/N_18/QUBO_18V_r_343.gpickle'
/bin/bash: /afs/ifh.de/user/t/tuccia/.profile: Permission denied
/bin/bash: /afs/ifh.de/user/t/tuccia/.profile: Permission denied
/lustre/fs24/group/cqta/atucci/environment/lib64/python3.9/site-packages/networkx/utils/backends.py:135: RuntimeWarning: networkx backend defined more than once: nx-loopback
  backends.update(_get_backends("networkx.backends"))
/bin/bash: /afs/ifh.de/user/t/tuccia/.profile: Permission denied
/lustre/fs24/group/cqta/atucci/environment/lib64/python3.9/site-packages/networkx/utils/backends.py:135: RuntimeWarning: networkx backend defined more than once: nx-loopback
  backends.update(_get_backends("networkx.backends"))
Traceback (most recent call last):
  File "/lustre/fs24/group/cqta/atucci/Random_cubo/Random_cubo_codes/run_qubo_iterate_adap_sorting_entropy.py", line 253, in <module>
    main()
  File "/lustre/fs24/group/cqta/atucci/Random_cubo/Random_cubo_codes/run_qubo_iterate_adap_sorting_entropy.py", line 118, in main
    with open(instance_dir + '/QUBO_' + str(n_qubits ) + 'V_'+ 'r_'+ str(r)+ '.gpickle', 'rb') as f:
FileNotFoundError: [Errno 2] No such file or directory: '../instances/complete/N_18/QUBO_18V_r_366.gpickle'
/bin/bash: /afs/ifh.de/user/t/tuccia/.profile: Permission denied
/lustre/fs24/group/cqta/atucci/environment/lib64/python3.9/site-packages/networkx/utils/backends.py:135: RuntimeWarning: networkx backend defined more than once: nx-loopback
  backends.update(_get_backends("networkx.backends"))
Traceback (most recent call last):
  File "/lustre/fs24/group/cqta/atucci/Random_cubo/Random_cubo_codes/run_qubo_iterate_adap_sorting_entropy.py", line 253, in <module>
    main()
  File "/lustre/fs24/group/cqta/atucci/Random_cubo/Random_cubo_codes/run_qubo_iterate_adap_sorting_entropy.py", line 118, in main
    with open(instance_dir + '/QUBO_' + str(n_qubits ) + 'V_'+ 'r_'+ str(r)+ '.gpickle', 'rb') as f:
FileNotFoundError: [Errno 2] No such file or directory: '../instances/complete/N_18/QUBO_18V_r_370.gpickle'
Traceback (most recent call last):
  File "/lustre/fs24/group/cqta/atucci/Random_cubo/Random_cubo_codes/run_qubo_iterate_adap_sorting_entropy.py", line 253, in <module>
    main()
  File "/lustre/fs24/group/cqta/atucci/Random_cubo/Random_cubo_codes/run_qubo_iterate_adap_sorting_entropy.py", line 118, in main
    with open(instance_dir + '/QUBO_' + str(n_qubits ) + 'V_'+ 'r_'+ str(r)+ '.gpickle', 'rb') as f:
FileNotFoundError: [Errno 2] No such file or directory: '../instances/complete/N_18/QUBO_18V_r_399.gpickle'
/bin/bash: /afs/ifh.de/user/t/tuccia/.profile: Permission denied
/bin/bash: /afs/ifh.de/user/t/tuccia/.profile: Permission denied
/lustre/fs24/group/cqta/atucci/environment/lib64/python3.9/site-packages/networkx/utils/backends.py:135: RuntimeWarning: networkx backend defined more than once: nx-loopback
  backends.update(_get_backends("networkx.backends"))
Traceback (most recent call last):
  File "/lustre/fs24/group/cqta/atucci/Random_cubo/Random_cubo_codes/run_qubo_iterate_adap_sorting_entropy.py", line 253, in <module>
    main()
  File "/lustre/fs24/group/cqta/atucci/Random_cubo/Random_cubo_codes/run_qubo_iterate_adap_sorting_entropy.py", line 118, in main
    with open(instance_dir + '/QUBO_' + str(n_qubits ) + 'V_'+ 'r_'+ str(r)+ '.gpickle', 'rb') as f:
FileNotFoundError: [Errno 2] No such file or directory: '../instances/complete/N_18/QUBO_18V_r_352.gpickle'
/bin/bash: /afs/ifh.de/user/t/tuccia/.profile: Permission denied
Traceback (most recent call last):
  File "/lustre/fs24/group/cqta/atucci/Random_cubo/Random_cubo_codes/run_qubo_iterate_adap_sorting_entropy.py", line 253, in <module>
    main()
  File "/lustre/fs24/group/cqta/atucci/Random_cubo/Random_cubo_codes/run_qubo_iterate_adap_sorting_entropy.py", line 118, in main
    with open(instance_dir + '/QUBO_' + str(n_qubits ) + 'V_'+ 'r_'+ str(r)+ '.gpickle', 'rb') as f:
FileNotFoundError: [Errno 2] No such file or directory: '../instances/complete/N_18/QUBO_18V_r_397.gpickle'
/bin/bash: /afs/ifh.de/user/t/tuccia/.profile: Permission denied
/lustre/fs24/group/cqta/atucci/environment/lib64/python3.9/site-packages/networkx/utils/backends.py:135: RuntimeWarning: networkx backend defined more than once: nx-loopback
  backends.update(_get_backends("networkx.backends"))
/lustre/fs24/group/cqta/atucci/environment/lib64/python3.9/site-packages/networkx/utils/backends.py:135: RuntimeWarning: networkx backend defined more than once: nx-loopback
  backends.update(_get_backends("networkx.backends"))
/lustre/fs24/group/cqta/atucci/environment/lib64/python3.9/site-packages/networkx/utils/backends.py:135: RuntimeWarning: networkx backend defined more than once: nx-loopback
  backends.update(_get_backends("networkx.backends"))
/lustre/fs24/group/cqta/atucci/environment/lib64/python3.9/site-packages/networkx/utils/backends.py:135: RuntimeWarning: networkx backend defined more than once: nx-loopback
  backends.update(_get_backends("networkx.backends"))
Traceback (most recent call last):
  File "/lustre/fs24/group/cqta/atucci/Random_cubo/Random_cubo_codes/run_qubo_iterate_adap_sorting_entropy.py", line 253, in <module>
    main()
  File "/lustre/fs24/group/cqta/atucci/Random_cubo/Random_cubo_codes/run_qubo_iterate_adap_sorting_entropy.py", line 118, in main
    with open(instance_dir + '/QUBO_' + str(n_qubits ) + 'V_'+ 'r_'+ str(r)+ '.gpickle', 'rb') as f:
FileNotFoundError: [Errno 2] No such file or directory: '../instances/complete/N_18/QUBO_18V_r_299.gpickle'
Traceback (most recent call last):
Traceback (most recent call last):
Traceback (most recent call last):
  File "/lustre/fs24/group/cqta/atucci/Random_cubo/Random_cubo_codes/run_qubo_iterate_adap_sorting_entropy.py", line 253, in <module>
  File "/lustre/fs24/group/cqta/atucci/Random_cubo/Random_cubo_codes/run_qubo_iterate_adap_sorting_entropy.py", line 253, in <module>
  File "/lustre/fs24/group/cqta/atucci/Random_cubo/Random_cubo_codes/run_qubo_iterate_adap_sorting_entropy.py", line 253, in <module>
    main()
    main()
  File "/lustre/fs24/group/cqta/atucci/Random_cubo/Random_cubo_codes/run_qubo_iterate_adap_sorting_entropy.py", line 118, in main
  File "/lustre/fs24/group/cqta/atucci/Random_cubo/Random_cubo_codes/run_qubo_iterate_adap_sorting_entropy.py", line 118, in main
    main()
  File "/lustre/fs24/group/cqta/atucci/Random_cubo/Random_cubo_codes/run_qubo_iterate_adap_sorting_entropy.py", line 118, in main
    with open(instance_dir + '/QUBO_' + str(n_qubits ) + 'V_'+ 'r_'+ str(r)+ '.gpickle', 'rb') as f:
FileNotFoundError: [Errno 2] No such file or directory: '../instances/complete/N_18/QUBO_18V_r_388.gpickle'
    with open(instance_dir + '/QUBO_' + str(n_qubits ) + 'V_'+ 'r_'+ str(r)+ '.gpickle', 'rb') as f:
FileNotFoundError: [Errno 2] No such file or directory: '../instances/complete/N_18/QUBO_18V_r_389.gpickle'
    with open(instance_dir + '/QUBO_' + str(n_qubits ) + 'V_'+ 'r_'+ str(r)+ '.gpickle', 'rb') as f:
FileNotFoundError: [Errno 2] No such file or directory: '../instances/complete/N_18/QUBO_18V_r_380.gpickle'
Traceback (most recent call last):
Traceback (most recent call last):
Traceback (most recent call last):
  File "/lustre/fs24/group/cqta/atucci/Random_cubo/Random_cubo_codes/run_qubo_iterate_adap_sorting_entropy.py", line 253, in <module>
  File "/lustre/fs24/group/cqta/atucci/Random_cubo/Random_cubo_codes/run_qubo_iterate_adap_sorting_entropy.py", line 253, in <module>
  File "/lustre/fs24/group/cqta/atucci/Random_cubo/Random_cubo_codes/run_qubo_iterate_adap_sorting_entropy.py", line 253, in <module>
    main()
    main()
  File "/lustre/fs24/group/cqta/atucci/Random_cubo/Random_cubo_codes/run_qubo_iterate_adap_sorting_entropy.py", line 118, in main
  File "/lustre/fs24/group/cqta/atucci/Random_cubo/Random_cubo_codes/run_qubo_iterate_adap_sorting_entropy.py", line 118, in main
    main()
  File "/lustre/fs24/group/cqta/atucci/Random_cubo/Random_cubo_codes/run_qubo_iterate_adap_sorting_entropy.py", line 118, in main
    with open(instance_dir + '/QUBO_' + str(n_qubits ) + 'V_'+ 'r_'+ str(r)+ '.gpickle', 'rb') as f:
FileNotFoundError: [Errno 2] No such file or directory: '../instances/complete/N_18/QUBO_18V_r_387.gpickle'
    with open(instance_dir + '/QUBO_' + str(n_qubits ) + 'V_'+ 'r_'+ str(r)+ '.gpickle', 'rb') as f:
FileNotFoundError: [Errno 2] No such file or directory: '../instances/complete/N_18/QUBO_18V_r_381.gpickle'
    with open(instance_dir + '/QUBO_' + str(n_qubits ) + 'V_'+ 'r_'+ str(r)+ '.gpickle', 'rb') as f:
FileNotFoundError: [Errno 2] No such file or directory: '../instances/complete/N_18/QUBO_18V_r_386.gpickle'
Traceback (most recent call last):
Traceback (most recent call last):
  File "/lustre/fs24/group/cqta/atucci/Random_cubo/Random_cubo_codes/run_qubo_iterate_adap_sorting_entropy.py", line 253, in <module>
  File "/lustre/fs24/group/cqta/atucci/Random_cubo/Random_cubo_codes/run_qubo_iterate_adap_sorting_entropy.py", line 253, in <module>
    main()
  File "/lustre/fs24/group/cqta/atucci/Random_cubo/Random_cubo_codes/run_qubo_iterate_adap_sorting_entropy.py", line 118, in main
    main()
  File "/lustre/fs24/group/cqta/atucci/Random_cubo/Random_cubo_codes/run_qubo_iterate_adap_sorting_entropy.py", line 118, in main
    with open(instance_dir + '/QUBO_' + str(n_qubits ) + 'V_'+ 'r_'+ str(r)+ '.gpickle', 'rb') as f:
FileNotFoundError: [Errno 2] No such file or directory: '../instances/complete/N_18/QUBO_18V_r_369.gpickle'
    with open(instance_dir + '/QUBO_' + str(n_qubits ) + 'V_'+ 'r_'+ str(r)+ '.gpickle', 'rb') as f:
FileNotFoundError: [Errno 2] No such file or directory: '../instances/complete/N_18/QUBO_18V_r_373.gpickle'
Traceback (most recent call last):
  File "/lustre/fs24/group/cqta/atucci/Random_cubo/Random_cubo_codes/run_qubo_iterate_adap_sorting_entropy.py", line 253, in <module>
    main()
  File "/lustre/fs24/group/cqta/atucci/Random_cubo/Random_cubo_codes/run_qubo_iterate_adap_sorting_entropy.py", line 118, in main
    with open(instance_dir + '/QUBO_' + str(n_qubits ) + 'V_'+ 'r_'+ str(r)+ '.gpickle', 'rb') as f:
FileNotFoundError: [Errno 2] No such file or directory: '../instances/complete/N_18/QUBO_18V_r_382.gpickle'
Traceback (most recent call last):
  File "/lustre/fs24/group/cqta/atucci/Random_cubo/Random_cubo_codes/run_qubo_iterate_adap_sorting_entropy.py", line 253, in <module>
    main()
  File "/lustre/fs24/group/cqta/atucci/Random_cubo/Random_cubo_codes/run_qubo_iterate_adap_sorting_entropy.py", line 118, in main
    with open(instance_dir + '/QUBO_' + str(n_qubits ) + 'V_'+ 'r_'+ str(r)+ '.gpickle', 'rb') as f:
FileNotFoundError: [Errno 2] No such file or directory: '../instances/complete/N_18/QUBO_18V_r_371.gpickle'
