/lustre/fs24/group/cqta/atucci/environment2/lib64/python3.9/site-packages/networkx/utils/backends.py:135: RuntimeWarning: networkx backend defined more than once: nx-loopback
  backends.update(_get_backends("networkx.backends"))
/bin/bash: /afs/ifh.de/user/t/tuccia/.profile: Permission denied
/bin/bash: /afs/ifh.de/user/t/tuccia/.profile: Permission denied
/lustre/fs24/group/cqta/atucci/environment2/lib64/python3.9/site-packages/networkx/utils/backends.py:135: RuntimeWarning: networkx backend defined more than once: nx-loopback
  backends.update(_get_backends("networkx.backends"))
Traceback (most recent call last):
  File "/lustre/fs24/group/cqta/atucci/Random_cubo/codes/run_qubo_shots.py", line 190, in <module>
    main()
  File "/lustre/fs24/group/cqta/atucci/Random_cubo/codes/run_qubo_shots.py", line 74, in main
    with open(instance_dir + '/QUBO_' + str(n_qubits ) + 'V_'+ 'r_'+ str(r)+ '.gpickle', 'rb') as f:
FileNotFoundError: [Errno 2] No such file or directory: '../instances/0.9/N_22/QUBO_22V_r_375.gpickle'
/lustre/fs24/group/cqta/atucci/environment2/lib64/python3.9/site-packages/networkx/utils/backends.py:135: RuntimeWarning: networkx backend defined more than once: nx-loopback
  backends.update(_get_backends("networkx.backends"))
Traceback (most recent call last):
  File "/lustre/fs24/group/cqta/atucci/Random_cubo/codes/run_qubo_shots.py", line 190, in <module>
    main()
  File "/lustre/fs24/group/cqta/atucci/Random_cubo/codes/run_qubo_shots.py", line 74, in main
    with open(instance_dir + '/QUBO_' + str(n_qubits ) + 'V_'+ 'r_'+ str(r)+ '.gpickle', 'rb') as f:
FileNotFoundError: [Errno 2] No such file or directory: '../instances/0.95/N_22/QUBO_22V_r_374.gpickle'
/bin/bash: /afs/ifh.de/user/t/tuccia/.profile: Permission denied
/bin/bash: /afs/ifh.de/user/t/tuccia/.profile: Permission denied
/bin/bash: /afs/ifh.de/user/t/tuccia/.profile: Permission denied
/bin/bash: /afs/ifh.de/user/t/tuccia/.profile: Permission denied
/bin/bash: /afs/ifh.de/user/t/tuccia/.profile: Permission denied
Traceback (most recent call last):
  File "/lustre/fs24/group/cqta/atucci/Random_cubo/codes/run_qubo_shots.py", line 190, in <module>
    main()
  File "/lustre/fs24/group/cqta/atucci/Random_cubo/codes/run_qubo_shots.py", line 74, in main
    with open(instance_dir + '/QUBO_' + str(n_qubits ) + 'V_'+ 'r_'+ str(r)+ '.gpickle', 'rb') as f:
FileNotFoundError: [Errno 2] No such file or directory: '../instances/0.95/N_22/QUBO_22V_r_375.gpickle'
/bin/bash: /afs/ifh.de/user/t/tuccia/.profile: Permission denied
/lustre/fs24/group/cqta/atucci/environment2/lib64/python3.9/site-packages/networkx/utils/backends.py:135: RuntimeWarning: networkx backend defined more than once: nx-loopback
  backends.update(_get_backends("networkx.backends"))
/bin/bash: /afs/ifh.de/user/t/tuccia/.profile: Permission denied
/bin/bash: /afs/ifh.de/user/t/tuccia/.profile: Permission denied
/lustre/fs24/group/cqta/atucci/environment2/lib64/python3.9/site-packages/networkx/utils/backends.py:135: RuntimeWarning: networkx backend defined more than once: nx-loopback
  backends.update(_get_backends("networkx.backends"))
/lustre/fs24/group/cqta/atucci/environment2/lib64/python3.9/site-packages/networkx/utils/backends.py:135: RuntimeWarning: networkx backend defined more than once: nx-loopback
  backends.update(_get_backends("networkx.backends"))
/bin/bash: /afs/ifh.de/user/t/tuccia/.profile: Permission denied
/lustre/fs24/group/cqta/atucci/environment2/lib64/python3.9/site-packages/networkx/utils/backends.py:135: RuntimeWarning: networkx backend defined more than once: nx-loopback
  backends.update(_get_backends("networkx.backends"))
/lustre/fs24/group/cqta/atucci/environment2/lib64/python3.9/site-packages/networkx/utils/backends.py:135: RuntimeWarning: networkx backend defined more than once: nx-loopback
  backends.update(_get_backends("networkx.backends"))
/lustre/fs24/group/cqta/atucci/environment2/lib64/python3.9/site-packages/networkx/utils/backends.py:135: RuntimeWarning: networkx backend defined more than once: nx-loopback
  backends.update(_get_backends("networkx.backends"))
/lustre/fs24/group/cqta/atucci/environment2/lib64/python3.9/site-packages/networkx/utils/backends.py:135: RuntimeWarning: networkx backend defined more than once: nx-loopback
  backends.update(_get_backends("networkx.backends"))
/lustre/fs24/group/cqta/atucci/environment2/lib64/python3.9/site-packages/networkx/utils/backends.py:135: RuntimeWarning: networkx backend defined more than once: nx-loopback
  backends.update(_get_backends("networkx.backends"))
/lustre/fs24/group/cqta/atucci/environment2/lib64/python3.9/site-packages/networkx/utils/backends.py:135: RuntimeWarning: networkx backend defined more than once: nx-loopback
  backends.update(_get_backends("networkx.backends"))
/bin/bash: /afs/ifh.de/user/t/tuccia/.profile: Permission denied
/bin/bash: /afs/ifh.de/user/t/tuccia/.profile: Permission denied
Traceback (most recent call last):
  File "/lustre/fs24/group/cqta/atucci/Random_cubo/codes/run_qubo_shots.py", line 190, in <module>
    main()
  File "/lustre/fs24/group/cqta/atucci/Random_cubo/codes/run_qubo_shots.py", line 74, in main
    with open(instance_dir + '/QUBO_' + str(n_qubits ) + 'V_'+ 'r_'+ str(r)+ '.gpickle', 'rb') as f:
FileNotFoundError: [Errno 2] No such file or directory: '../instances/0.9/N_22/QUBO_22V_r_380.gpickle'
/lustre/fs24/group/cqta/atucci/environment2/lib64/python3.9/site-packages/networkx/utils/backends.py:135: RuntimeWarning: networkx backend defined more than once: nx-loopback
  backends.update(_get_backends("networkx.backends"))
/lustre/fs24/group/cqta/atucci/environment2/lib64/python3.9/site-packages/networkx/utils/backends.py:135: RuntimeWarning: networkx backend defined more than once: nx-loopback
  backends.update(_get_backends("networkx.backends"))
/bin/bash: /afs/ifh.de/user/t/tuccia/.profile: Permission denied
Traceback (most recent call last):
  File "/lustre/fs24/group/cqta/atucci/Random_cubo/codes/run_qubo_shots.py", line 190, in <module>
    main()
  File "/lustre/fs24/group/cqta/atucci/Random_cubo/codes/run_qubo_shots.py", line 74, in main
    with open(instance_dir + '/QUBO_' + str(n_qubits ) + 'V_'+ 'r_'+ str(r)+ '.gpickle', 'rb') as f:
FileNotFoundError: [Errno 2] No such file or directory: '../instances/0.95/N_22/QUBO_22V_r_385.gpickle'
Traceback (most recent call last):
  File "/lustre/fs24/group/cqta/atucci/Random_cubo/codes/run_qubo_shots.py", line 190, in <module>
    main()
  File "/lustre/fs24/group/cqta/atucci/Random_cubo/codes/run_qubo_shots.py", line 74, in main
    with open(instance_dir + '/QUBO_' + str(n_qubits ) + 'V_'+ 'r_'+ str(r)+ '.gpickle', 'rb') as f:
FileNotFoundError: [Errno 2] No such file or directory: '../instances/0.95/N_22/QUBO_22V_r_389.gpickle'
/bin/bash: /afs/ifh.de/user/t/tuccia/.profile: Permission denied
/lustre/fs24/group/cqta/atucci/environment2/lib64/python3.9/site-packages/networkx/utils/backends.py:135: RuntimeWarning: networkx backend defined more than once: nx-loopback
  backends.update(_get_backends("networkx.backends"))
/bin/bash: /afs/ifh.de/user/t/tuccia/.profile: Permission denied
/lustre/fs24/group/cqta/atucci/environment2/lib64/python3.9/site-packages/networkx/utils/backends.py:135: RuntimeWarning: networkx backend defined more than once: nx-loopback
  backends.update(_get_backends("networkx.backends"))
/lustre/fs24/group/cqta/atucci/environment2/lib64/python3.9/site-packages/networkx/utils/backends.py:135: RuntimeWarning: networkx backend defined more than once: nx-loopback
  backends.update(_get_backends("networkx.backends"))
Traceback (most recent call last):
  File "/lustre/fs24/group/cqta/atucci/Random_cubo/codes/run_qubo_shots.py", line 190, in <module>
    main()
  File "/lustre/fs24/group/cqta/atucci/Random_cubo/codes/run_qubo_shots.py", line 74, in main
    with open(instance_dir + '/QUBO_' + str(n_qubits ) + 'V_'+ 'r_'+ str(r)+ '.gpickle', 'rb') as f:
FileNotFoundError: [Errno 2] No such file or directory: '../instances/0.95/N_22/QUBO_22V_r_383.gpickle'
/bin/bash: /afs/ifh.de/user/t/tuccia/.profile: Permission denied
Traceback (most recent call last):
  File "/lustre/fs24/group/cqta/atucci/Random_cubo/codes/run_qubo_shots.py", line 190, in <module>
    main()
  File "/lustre/fs24/group/cqta/atucci/Random_cubo/codes/run_qubo_shots.py", line 74, in main
    with open(instance_dir + '/QUBO_' + str(n_qubits ) + 'V_'+ 'r_'+ str(r)+ '.gpickle', 'rb') as f:
FileNotFoundError: [Errno 2] No such file or directory: '../instances/0.9/N_22/QUBO_22V_r_388.gpickle'
Traceback (most recent call last):
  File "/lustre/fs24/group/cqta/atucci/Random_cubo/codes/run_qubo_shots.py", line 190, in <module>
    main()
  File "/lustre/fs24/group/cqta/atucci/Random_cubo/codes/run_qubo_shots.py", line 74, in main
    with open(instance_dir + '/QUBO_' + str(n_qubits ) + 'V_'+ 'r_'+ str(r)+ '.gpickle', 'rb') as f:
FileNotFoundError: [Errno 2] No such file or directory: '../instances/0.95/N_22/QUBO_22V_r_382.gpickle'
Traceback (most recent call last):
  File "/lustre/fs24/group/cqta/atucci/Random_cubo/codes/run_qubo_shots.py", line 190, in <module>
    main()
  File "/lustre/fs24/group/cqta/atucci/Random_cubo/codes/run_qubo_shots.py", line 74, in main
    with open(instance_dir + '/QUBO_' + str(n_qubits ) + 'V_'+ 'r_'+ str(r)+ '.gpickle', 'rb') as f:
FileNotFoundError: [Errno 2] No such file or directory: '../instances/0.9/N_22/QUBO_22V_r_381.gpickle'
/lustre/fs24/group/cqta/atucci/environment2/lib64/python3.9/site-packages/networkx/utils/backends.py:135: RuntimeWarning: networkx backend defined more than once: nx-loopback
  backends.update(_get_backends("networkx.backends"))
/bin/bash: /afs/ifh.de/user/t/tuccia/.profile: Permission denied
/lustre/fs24/group/cqta/atucci/environment2/lib64/python3.9/site-packages/networkx/utils/backends.py:135: RuntimeWarning: networkx backend defined more than once: nx-loopback
  backends.update(_get_backends("networkx.backends"))
/bin/bash: /afs/ifh.de/user/t/tuccia/.profile: Permission denied
Traceback (most recent call last):
  File "/lustre/fs24/group/cqta/atucci/Random_cubo/codes/run_qubo_shots.py", line 190, in <module>
    main()
  File "/lustre/fs24/group/cqta/atucci/Random_cubo/codes/run_qubo_shots.py", line 74, in main
    with open(instance_dir + '/QUBO_' + str(n_qubits ) + 'V_'+ 'r_'+ str(r)+ '.gpickle', 'rb') as f:
FileNotFoundError: [Errno 2] No such file or directory: '../instances/0.95/N_22/QUBO_22V_r_378.gpickle'
/lustre/fs24/group/cqta/atucci/environment2/lib64/python3.9/site-packages/networkx/utils/backends.py:135: RuntimeWarning: networkx backend defined more than once: nx-loopback
  backends.update(_get_backends("networkx.backends"))
/bin/bash: /afs/ifh.de/user/t/tuccia/.profile: Permission denied
Traceback (most recent call last):
  File "/lustre/fs24/group/cqta/atucci/Random_cubo/codes/run_qubo_shots.py", line 190, in <module>
    main()
  File "/lustre/fs24/group/cqta/atucci/Random_cubo/codes/run_qubo_shots.py", line 74, in main
    with open(instance_dir + '/QUBO_' + str(n_qubits ) + 'V_'+ 'r_'+ str(r)+ '.gpickle', 'rb') as f:
FileNotFoundError: [Errno 2] No such file or directory: '../instances/0.95/N_22/QUBO_22V_r_376.gpickle'
/bin/bash: /afs/ifh.de/user/t/tuccia/.profile: Permission denied
/bin/bash: /afs/ifh.de/user/t/tuccia/.profile: Permission denied
/bin/bash: /afs/ifh.de/user/t/tuccia/.profile: Permission denied
/bin/bash: /afs/ifh.de/user/t/tuccia/.profile: Permission denied
/bin/bash: /afs/ifh.de/user/t/tuccia/.profile: Permission denied
/bin/bash: /afs/ifh.de/user/t/tuccia/.profile: Permission denied
Traceback (most recent call last):
  File "/lustre/fs24/group/cqta/atucci/Random_cubo/codes/run_qubo_shots.py", line 190, in <module>
    main()
  File "/lustre/fs24/group/cqta/atucci/Random_cubo/codes/run_qubo_shots.py", line 74, in main
    with open(instance_dir + '/QUBO_' + str(n_qubits ) + 'V_'+ 'r_'+ str(r)+ '.gpickle', 'rb') as f:
FileNotFoundError: [Errno 2] No such file or directory: '../instances/0.9/N_22/QUBO_22V_r_286.gpickle'
/lustre/fs24/group/cqta/atucci/environment2/lib64/python3.9/site-packages/networkx/utils/backends.py:135: RuntimeWarning: networkx backend defined more than once: nx-loopback
  backends.update(_get_backends("networkx.backends"))
/lustre/fs24/group/cqta/atucci/environment2/lib64/python3.9/site-packages/networkx/utils/backends.py:135: RuntimeWarning: networkx backend defined more than once: nx-loopback
  backends.update(_get_backends("networkx.backends"))
/lustre/fs24/group/cqta/atucci/environment2/lib64/python3.9/site-packages/networkx/utils/backends.py:135: RuntimeWarning: networkx backend defined more than once: nx-loopback
  backends.update(_get_backends("networkx.backends"))
/bin/bash: /afs/ifh.de/user/t/tuccia/.profile: Permission denied
/bin/bash: /afs/ifh.de/user/t/tuccia/.profile: Permission denied
/lustre/fs24/group/cqta/atucci/environment2/lib64/python3.9/site-packages/networkx/utils/backends.py:135: RuntimeWarning: networkx backend defined more than once: nx-loopback
  backends.update(_get_backends("networkx.backends"))
/bin/bash: /afs/ifh.de/user/t/tuccia/.profile: Permission denied
/lustre/fs24/group/cqta/atucci/environment2/lib64/python3.9/site-packages/networkx/utils/backends.py:135: RuntimeWarning: networkx backend defined more than once: nx-loopback
  backends.update(_get_backends("networkx.backends"))
/lustre/fs24/group/cqta/atucci/environment2/lib64/python3.9/site-packages/networkx/utils/backends.py:135: RuntimeWarning: networkx backend defined more than once: nx-loopback
  backends.update(_get_backends("networkx.backends"))
/lustre/fs24/group/cqta/atucci/environment2/lib64/python3.9/site-packages/networkx/utils/backends.py:135: RuntimeWarning: networkx backend defined more than once: nx-loopback
  backends.update(_get_backends("networkx.backends"))
/bin/bash: /afs/ifh.de/user/t/tuccia/.profile: Permission denied
/bin/bash: /afs/ifh.de/user/t/tuccia/.profile: Permission denied
/lustre/fs24/group/cqta/atucci/environment2/lib64/python3.9/site-packages/networkx/utils/backends.py:135: RuntimeWarning: networkx backend defined more than once: nx-loopback
  backends.update(_get_backends("networkx.backends"))
/lustre/fs24/group/cqta/atucci/environment2/lib64/python3.9/site-packages/networkx/utils/backends.py:135: RuntimeWarning: networkx backend defined more than once: nx-loopback
  backends.update(_get_backends("networkx.backends"))
/lustre/fs24/group/cqta/atucci/environment2/lib64/python3.9/site-packages/networkx/utils/backends.py:135: RuntimeWarning: networkx backend defined more than once: nx-loopback
  backends.update(_get_backends("networkx.backends"))
/lustre/fs24/group/cqta/atucci/environment2/lib64/python3.9/site-packages/networkx/utils/backends.py:135: RuntimeWarning: networkx backend defined more than once: nx-loopback
  backends.update(_get_backends("networkx.backends"))
/lustre/fs24/group/cqta/atucci/environment2/lib64/python3.9/site-packages/networkx/utils/backends.py:135: RuntimeWarning: networkx backend defined more than once: nx-loopback
  backends.update(_get_backends("networkx.backends"))
/bin/bash: /afs/ifh.de/user/t/tuccia/.profile: Permission denied
/bin/bash: /afs/ifh.de/user/t/tuccia/.profile: Permission denied
/lustre/fs24/group/cqta/atucci/environment2/lib64/python3.9/site-packages/networkx/utils/backends.py:135: RuntimeWarning: networkx backend defined more than once: nx-loopback
  backends.update(_get_backends("networkx.backends"))
/lustre/fs24/group/cqta/atucci/environment2/lib64/python3.9/site-packages/networkx/utils/backends.py:135: RuntimeWarning: networkx backend defined more than once: nx-loopback
  backends.update(_get_backends("networkx.backends"))
Traceback (most recent call last):
  File "/lustre/fs24/group/cqta/atucci/Random_cubo/codes/run_qubo_shots.py", line 190, in <module>
    main()
  File "/lustre/fs24/group/cqta/atucci/Random_cubo/codes/run_qubo_shots.py", line 74, in main
    with open(instance_dir + '/QUBO_' + str(n_qubits ) + 'V_'+ 'r_'+ str(r)+ '.gpickle', 'rb') as f:
FileNotFoundError: [Errno 2] No such file or directory: '../instances/0.95/N_22/QUBO_22V_r_388.gpickle'
Traceback (most recent call last):
  File "/lustre/fs24/group/cqta/atucci/Random_cubo/codes/run_qubo_shots.py", line 190, in <module>
    main()
  File "/lustre/fs24/group/cqta/atucci/Random_cubo/codes/run_qubo_shots.py", line 74, in main
    with open(instance_dir + '/QUBO_' + str(n_qubits ) + 'V_'+ 'r_'+ str(r)+ '.gpickle', 'rb') as f:
FileNotFoundError: [Errno 2] No such file or directory: '../instances/0.95/N_22/QUBO_22V_r_381.gpickle'
Traceback (most recent call last):
  File "/lustre/fs24/group/cqta/atucci/Random_cubo/codes/run_qubo_shots.py", line 190, in <module>
    main()
  File "/lustre/fs24/group/cqta/atucci/Random_cubo/codes/run_qubo_shots.py", line 74, in main
    with open(instance_dir + '/QUBO_' + str(n_qubits ) + 'V_'+ 'r_'+ str(r)+ '.gpickle', 'rb') as f:
FileNotFoundError: [Errno 2] No such file or directory: '../instances/0.9/N_22/QUBO_22V_r_387.gpickle'
Traceback (most recent call last):
  File "/lustre/fs24/group/cqta/atucci/Random_cubo/codes/run_qubo_shots.py", line 190, in <module>
    main()
  File "/lustre/fs24/group/cqta/atucci/Random_cubo/codes/run_qubo_shots.py", line 74, in main
    with open(instance_dir + '/QUBO_' + str(n_qubits ) + 'V_'+ 'r_'+ str(r)+ '.gpickle', 'rb') as f:
FileNotFoundError: [Errno 2] No such file or directory: '../instances/0.9/N_22/QUBO_22V_r_399.gpickle'
Traceback (most recent call last):
  File "/lustre/fs24/group/cqta/atucci/Random_cubo/codes/run_qubo_shots.py", line 190, in <module>
    main()
  File "/lustre/fs24/group/cqta/atucci/Random_cubo/codes/run_qubo_shots.py", line 74, in main
    with open(instance_dir + '/QUBO_' + str(n_qubits ) + 'V_'+ 'r_'+ str(r)+ '.gpickle', 'rb') as f:
FileNotFoundError: [Errno 2] No such file or directory: '../instances/0.9/N_22/QUBO_22V_r_385.gpickle'
/bin/bash: /afs/ifh.de/user/t/tuccia/.profile: Permission denied
/bin/bash: /afs/ifh.de/user/t/tuccia/.profile: Permission denied
Traceback (most recent call last):
  File "/lustre/fs24/group/cqta/atucci/Random_cubo/codes/run_qubo_shots.py", line 190, in <module>
    main()
  File "/lustre/fs24/group/cqta/atucci/Random_cubo/codes/run_qubo_shots.py", line 74, in main
    with open(instance_dir + '/QUBO_' + str(n_qubits ) + 'V_'+ 'r_'+ str(r)+ '.gpickle', 'rb') as f:
FileNotFoundError: [Errno 2] No such file or directory: '../instances/0.9/N_22/QUBO_22V_r_384.gpickle'
/lustre/fs24/group/cqta/atucci/environment2/lib64/python3.9/site-packages/networkx/utils/backends.py:135: RuntimeWarning: networkx backend defined more than once: nx-loopback
  backends.update(_get_backends("networkx.backends"))
Traceback (most recent call last):
  File "/lustre/fs24/group/cqta/atucci/Random_cubo/codes/run_qubo_shots.py", line 190, in <module>
    main()
  File "/lustre/fs24/group/cqta/atucci/Random_cubo/codes/run_qubo_shots.py", line 74, in main
    with open(instance_dir + '/QUBO_' + str(n_qubits ) + 'V_'+ 'r_'+ str(r)+ '.gpickle', 'rb') as f:
FileNotFoundError: [Errno 2] No such file or directory: '../instances/0.9/N_22/QUBO_22V_r_383.gpickle'
/lustre/fs24/group/cqta/atucci/environment2/lib64/python3.9/site-packages/networkx/utils/backends.py:135: RuntimeWarning: networkx backend defined more than once: nx-loopback
  backends.update(_get_backends("networkx.backends"))
Traceback (most recent call last):
  File "/lustre/fs24/group/cqta/atucci/Random_cubo/codes/run_qubo_shots.py", line 190, in <module>
    main()
  File "/lustre/fs24/group/cqta/atucci/Random_cubo/codes/run_qubo_shots.py", line 74, in main
    with open(instance_dir + '/QUBO_' + str(n_qubits ) + 'V_'+ 'r_'+ str(r)+ '.gpickle', 'rb') as f:
FileNotFoundError: [Errno 2] No such file or directory: '../instances/0.95/N_22/QUBO_22V_r_386.gpickle'
/bin/bash: /afs/ifh.de/user/t/tuccia/.profile: Permission denied
Traceback (most recent call last):
  File "/lustre/fs24/group/cqta/atucci/Random_cubo/codes/run_qubo_shots.py", line 190, in <module>
    main()
  File "/lustre/fs24/group/cqta/atucci/Random_cubo/codes/run_qubo_shots.py", line 74, in main
    with open(instance_dir + '/QUBO_' + str(n_qubits ) + 'V_'+ 'r_'+ str(r)+ '.gpickle', 'rb') as f:
FileNotFoundError: [Errno 2] No such file or directory: '../instances/0.9/N_22/QUBO_22V_r_391.gpickle'
/bin/bash: /afs/ifh.de/user/t/tuccia/.profile: Permission denied
/lustre/fs24/group/cqta/atucci/environment2/lib64/python3.9/site-packages/networkx/utils/backends.py:135: RuntimeWarning: networkx backend defined more than once: nx-loopback
  backends.update(_get_backends("networkx.backends"))
Traceback (most recent call last):
  File "/lustre/fs24/group/cqta/atucci/Random_cubo/codes/run_qubo_shots.py", line 190, in <module>
    main()
  File "/lustre/fs24/group/cqta/atucci/Random_cubo/codes/run_qubo_shots.py", line 74, in main
    with open(instance_dir + '/QUBO_' + str(n_qubits ) + 'V_'+ 'r_'+ str(r)+ '.gpickle', 'rb') as f:
FileNotFoundError: [Errno 2] No such file or directory: '../instances/0.95/N_22/QUBO_22V_r_392.gpickle'
/lustre/fs24/group/cqta/atucci/environment2/lib64/python3.9/site-packages/networkx/utils/backends.py:135: RuntimeWarning: networkx backend defined more than once: nx-loopback
  backends.update(_get_backends("networkx.backends"))
Traceback (most recent call last):
  File "/lustre/fs24/group/cqta/atucci/Random_cubo/codes/run_qubo_shots.py", line 190, in <module>
    main()
  File "/lustre/fs24/group/cqta/atucci/Random_cubo/codes/run_qubo_shots.py", line 74, in main
    with open(instance_dir + '/QUBO_' + str(n_qubits ) + 'V_'+ 'r_'+ str(r)+ '.gpickle', 'rb') as f:
FileNotFoundError: [Errno 2] No such file or directory: '../instances/0.95/N_22/QUBO_22V_r_379.gpickle'
Traceback (most recent call last):
  File "/lustre/fs24/group/cqta/atucci/Random_cubo/codes/run_qubo_shots.py", line 190, in <module>
    main()
  File "/lustre/fs24/group/cqta/atucci/Random_cubo/codes/run_qubo_shots.py", line 74, in main
    with open(instance_dir + '/QUBO_' + str(n_qubits ) + 'V_'+ 'r_'+ str(r)+ '.gpickle', 'rb') as f:
FileNotFoundError: [Errno 2] No such file or directory: '../instances/0.95/N_22/QUBO_22V_r_398.gpickle'
/bin/bash: /afs/ifh.de/user/t/tuccia/.profile: Permission denied
/lustre/fs24/group/cqta/atucci/environment2/lib64/python3.9/site-packages/networkx/utils/backends.py:135: RuntimeWarning: networkx backend defined more than once: nx-loopback
  backends.update(_get_backends("networkx.backends"))
/bin/bash: /afs/ifh.de/user/t/tuccia/.profile: Permission denied
Traceback (most recent call last):
  File "/lustre/fs24/group/cqta/atucci/Random_cubo/codes/run_qubo_shots.py", line 190, in <module>
    main()
  File "/lustre/fs24/group/cqta/atucci/Random_cubo/codes/run_qubo_shots.py", line 74, in main
    with open(instance_dir + '/QUBO_' + str(n_qubits ) + 'V_'+ 'r_'+ str(r)+ '.gpickle', 'rb') as f:
FileNotFoundError: [Errno 2] No such file or directory: '../instances/0.95/N_22/QUBO_22V_r_394.gpickle'
Traceback (most recent call last):
  File "/lustre/fs24/group/cqta/atucci/Random_cubo/codes/run_qubo_shots.py", line 190, in <module>
    main()
  File "/lustre/fs24/group/cqta/atucci/Random_cubo/codes/run_qubo_shots.py", line 74, in main
    with open(instance_dir + '/QUBO_' + str(n_qubits ) + 'V_'+ 'r_'+ str(r)+ '.gpickle', 'rb') as f:
FileNotFoundError: [Errno 2] No such file or directory: '../instances/0.9/N_22/QUBO_22V_r_376.gpickle'
/lustre/fs24/group/cqta/atucci/environment2/lib64/python3.9/site-packages/networkx/utils/backends.py:135: RuntimeWarning: networkx backend defined more than once: nx-loopback
  backends.update(_get_backends("networkx.backends"))
/bin/bash: /afs/ifh.de/user/t/tuccia/.profile: Permission denied
/bin/bash: /afs/ifh.de/user/t/tuccia/.profile: Permission denied
/bin/bash: /afs/ifh.de/user/t/tuccia/.profile: Permission denied
Traceback (most recent call last):
/bin/bash: /afs/ifh.de/user/t/tuccia/.profile: Permission denied
  File "/lustre/fs24/group/cqta/atucci/Random_cubo/codes/run_qubo_shots.py", line 190, in <module>
    main()
  File "/lustre/fs24/group/cqta/atucci/Random_cubo/codes/run_qubo_shots.py", line 74, in main
    with open(instance_dir + '/QUBO_' + str(n_qubits ) + 'V_'+ 'r_'+ str(r)+ '.gpickle', 'rb') as f:
FileNotFoundError: [Errno 2] No such file or directory: '../instances/0.9/N_22/QUBO_22V_r_382.gpickle'
/lustre/fs24/group/cqta/atucci/environment2/lib64/python3.9/site-packages/networkx/utils/backends.py:135: RuntimeWarning: networkx backend defined more than once: nx-loopback
  backends.update(_get_backends("networkx.backends"))
/lustre/fs24/group/cqta/atucci/environment2/lib64/python3.9/site-packages/networkx/utils/backends.py:135: RuntimeWarning: networkx backend defined more than once: nx-loopback
  backends.update(_get_backends("networkx.backends"))
/bin/bash: /afs/ifh.de/user/t/tuccia/.profile: Permission denied
/bin/bash: /afs/ifh.de/user/t/tuccia/.profile: Permission denied
/bin/bash: /afs/ifh.de/user/t/tuccia/.profile: Permission denied
/lustre/fs24/group/cqta/atucci/environment2/lib64/python3.9/site-packages/networkx/utils/backends.py:135: RuntimeWarning: networkx backend defined more than once: nx-loopback
  backends.update(_get_backends("networkx.backends"))
/lustre/fs24/group/cqta/atucci/environment2/lib64/python3.9/site-packages/networkx/utils/backends.py:135: RuntimeWarning: networkx backend defined more than once: nx-loopback
  backends.update(_get_backends("networkx.backends"))
/bin/bash: /afs/ifh.de/user/t/tuccia/.profile: Permission denied
/lustre/fs24/group/cqta/atucci/environment2/lib64/python3.9/site-packages/networkx/utils/backends.py:135: RuntimeWarning: networkx backend defined more than once: nx-loopback
  backends.update(_get_backends("networkx.backends"))
/bin/bash: /afs/ifh.de/user/t/tuccia/.profile: Permission denied
/lustre/fs24/group/cqta/atucci/environment2/lib64/python3.9/site-packages/networkx/utils/backends.py:135: RuntimeWarning: networkx backend defined more than once: nx-loopback
  backends.update(_get_backends("networkx.backends"))
/lustre/fs24/group/cqta/atucci/environment2/lib64/python3.9/site-packages/networkx/utils/backends.py:135: RuntimeWarning: networkx backend defined more than once: nx-loopback
  backends.update(_get_backends("networkx.backends"))
/lustre/fs24/group/cqta/atucci/environment2/lib64/python3.9/site-packages/networkx/utils/backends.py:135: RuntimeWarning: networkx backend defined more than once: nx-loopback
  backends.update(_get_backends("networkx.backends"))
/lustre/fs24/group/cqta/atucci/environment2/lib64/python3.9/site-packages/networkx/utils/backends.py:135: RuntimeWarning: networkx backend defined more than once: nx-loopback
  backends.update(_get_backends("networkx.backends"))
Traceback (most recent call last):
  File "/lustre/fs24/group/cqta/atucci/Random_cubo/codes/run_qubo_shots.py", line 190, in <module>
    main()
  File "/lustre/fs24/group/cqta/atucci/Random_cubo/codes/run_qubo_shots.py", line 74, in main
    with open(instance_dir + '/QUBO_' + str(n_qubits ) + 'V_'+ 'r_'+ str(r)+ '.gpickle', 'rb') as f:
FileNotFoundError: [Errno 2] No such file or directory: '../instances/0.95/N_22/QUBO_22V_r_395.gpickle'
/bin/bash: /afs/ifh.de/user/t/tuccia/.profile: Permission denied
/bin/bash: /afs/ifh.de/user/t/tuccia/.profile: Permission denied
/lustre/fs24/group/cqta/atucci/environment2/lib64/python3.9/site-packages/networkx/utils/backends.py:135: RuntimeWarning: networkx backend defined more than once: nx-loopback
  backends.update(_get_backends("networkx.backends"))
/lustre/fs24/group/cqta/atucci/environment2/lib64/python3.9/site-packages/networkx/utils/backends.py:135: RuntimeWarning: networkx backend defined more than once: nx-loopback
  backends.update(_get_backends("networkx.backends"))
Traceback (most recent call last):
  File "/lustre/fs24/group/cqta/atucci/Random_cubo/codes/run_qubo_shots.py", line 190, in <module>
    main()
  File "/lustre/fs24/group/cqta/atucci/Random_cubo/codes/run_qubo_shots.py", line 74, in main
    with open(instance_dir + '/QUBO_' + str(n_qubits ) + 'V_'+ 'r_'+ str(r)+ '.gpickle', 'rb') as f:
FileNotFoundError: [Errno 2] No such file or directory: '../instances/0.9/N_22/QUBO_22V_r_389.gpickle'
Traceback (most recent call last):
  File "/lustre/fs24/group/cqta/atucci/Random_cubo/codes/run_qubo_shots.py", line 190, in <module>
    main()
  File "/lustre/fs24/group/cqta/atucci/Random_cubo/codes/run_qubo_shots.py", line 74, in main
    with open(instance_dir + '/QUBO_' + str(n_qubits ) + 'V_'+ 'r_'+ str(r)+ '.gpickle', 'rb') as f:
FileNotFoundError: [Errno 2] No such file or directory: '../instances/0.95/N_22/QUBO_22V_r_387.gpickle'
Traceback (most recent call last):
  File "/lustre/fs24/group/cqta/atucci/Random_cubo/codes/run_qubo_shots.py", line 190, in <module>
    main()
  File "/lustre/fs24/group/cqta/atucci/Random_cubo/codes/run_qubo_shots.py", line 74, in main
    with open(instance_dir + '/QUBO_' + str(n_qubits ) + 'V_'+ 'r_'+ str(r)+ '.gpickle', 'rb') as f:
FileNotFoundError: [Errno 2] No such file or directory: '../instances/0.9/N_22/QUBO_22V_r_397.gpickle'
/bin/bash: /afs/ifh.de/user/t/tuccia/.profile: Permission denied
/bin/bash: /afs/ifh.de/user/t/tuccia/.profile: Permission denied
Traceback (most recent call last):
  File "/lustre/fs24/group/cqta/atucci/Random_cubo/codes/run_qubo_shots.py", line 190, in <module>
    main()
  File "/lustre/fs24/group/cqta/atucci/Random_cubo/codes/run_qubo_shots.py", line 74, in main
    with open(instance_dir + '/QUBO_' + str(n_qubits ) + 'V_'+ 'r_'+ str(r)+ '.gpickle', 'rb') as f:
FileNotFoundError: [Errno 2] No such file or directory: '../instances/0.95/N_22/QUBO_22V_r_393.gpickle'
/lustre/fs24/group/cqta/atucci/environment2/lib64/python3.9/site-packages/networkx/utils/backends.py:135: RuntimeWarning: networkx backend defined more than once: nx-loopback
  backends.update(_get_backends("networkx.backends"))
Traceback (most recent call last):
  File "/lustre/fs24/group/cqta/atucci/Random_cubo/codes/run_qubo_shots.py", line 190, in <module>
    main()
  File "/lustre/fs24/group/cqta/atucci/Random_cubo/codes/run_qubo_shots.py", line 74, in main
    with open(instance_dir + '/QUBO_' + str(n_qubits ) + 'V_'+ 'r_'+ str(r)+ '.gpickle', 'rb') as f:
FileNotFoundError: [Errno 2] No such file or directory: '../instances/0.9/N_22/QUBO_22V_r_386.gpickle'
/lustre/fs24/group/cqta/atucci/environment2/lib64/python3.9/site-packages/networkx/utils/backends.py:135: RuntimeWarning: networkx backend defined more than once: nx-loopback
  backends.update(_get_backends("networkx.backends"))
Traceback (most recent call last):
  File "/lustre/fs24/group/cqta/atucci/Random_cubo/codes/run_qubo_shots.py", line 190, in <module>
    main()
  File "/lustre/fs24/group/cqta/atucci/Random_cubo/codes/run_qubo_shots.py", line 74, in main
    with open(instance_dir + '/QUBO_' + str(n_qubits ) + 'V_'+ 'r_'+ str(r)+ '.gpickle', 'rb') as f:
FileNotFoundError: [Errno 2] No such file or directory: '../instances/0.9/N_22/QUBO_22V_r_390.gpickle'
Traceback (most recent call last):
  File "/lustre/fs24/group/cqta/atucci/Random_cubo/codes/run_qubo_shots.py", line 190, in <module>
    main()
  File "/lustre/fs24/group/cqta/atucci/Random_cubo/codes/run_qubo_shots.py", line 74, in main
    with open(instance_dir + '/QUBO_' + str(n_qubits ) + 'V_'+ 'r_'+ str(r)+ '.gpickle', 'rb') as f:
FileNotFoundError: [Errno 2] No such file or directory: '../instances/0.95/N_22/QUBO_22V_r_384.gpickle'
Traceback (most recent call last):
  File "/lustre/fs24/group/cqta/atucci/Random_cubo/codes/run_qubo_shots.py", line 190, in <module>
    main()
  File "/lustre/fs24/group/cqta/atucci/Random_cubo/codes/run_qubo_shots.py", line 74, in main
    with open(instance_dir + '/QUBO_' + str(n_qubits ) + 'V_'+ 'r_'+ str(r)+ '.gpickle', 'rb') as f:
FileNotFoundError: [Errno 2] No such file or directory: '../instances/0.9/N_22/QUBO_22V_r_396.gpickle'
/bin/bash: /afs/ifh.de/user/t/tuccia/.profile: Permission denied
/lustre/fs24/group/cqta/atucci/environment2/lib64/python3.9/site-packages/networkx/utils/backends.py:135: RuntimeWarning: networkx backend defined more than once: nx-loopback
  backends.update(_get_backends("networkx.backends"))
/bin/bash: /afs/ifh.de/user/t/tuccia/.profile: Permission denied
/lustre/fs24/group/cqta/atucci/environment2/lib64/python3.9/site-packages/networkx/utils/backends.py:135: RuntimeWarning: networkx backend defined more than once: nx-loopback
  backends.update(_get_backends("networkx.backends"))
/bin/bash: /afs/ifh.de/user/t/tuccia/.profile: Permission denied
/lustre/fs24/group/cqta/atucci/environment2/lib64/python3.9/site-packages/networkx/utils/backends.py:135: RuntimeWarning: networkx backend defined more than once: nx-loopback
  backends.update(_get_backends("networkx.backends"))
Traceback (most recent call last):
  File "/lustre/fs24/group/cqta/atucci/Random_cubo/codes/run_qubo_shots.py", line 190, in <module>
    main()
  File "/lustre/fs24/group/cqta/atucci/Random_cubo/codes/run_qubo_shots.py", line 74, in main
    with open(instance_dir + '/QUBO_' + str(n_qubits ) + 'V_'+ 'r_'+ str(r)+ '.gpickle', 'rb') as f:
FileNotFoundError: [Errno 2] No such file or directory: '../instances/0.9/N_22/QUBO_22V_r_398.gpickle'
/bin/bash: /afs/ifh.de/user/t/tuccia/.profile: Permission denied
/lustre/fs24/group/cqta/atucci/environment2/lib64/python3.9/site-packages/networkx/utils/backends.py:135: RuntimeWarning: networkx backend defined more than once: nx-loopback
  backends.update(_get_backends("networkx.backends"))
/bin/bash: /afs/ifh.de/user/t/tuccia/.profile: Permission denied
/bin/bash: /afs/ifh.de/user/t/tuccia/.profile: Permission denied
/bin/bash: /afs/ifh.de/user/t/tuccia/.profile: Permission denied
/lustre/fs24/group/cqta/atucci/environment2/lib64/python3.9/site-packages/networkx/utils/backends.py:135: RuntimeWarning: networkx backend defined more than once: nx-loopback
  backends.update(_get_backends("networkx.backends"))
/lustre/fs24/group/cqta/atucci/environment2/lib64/python3.9/site-packages/networkx/utils/backends.py:135: RuntimeWarning: networkx backend defined more than once: nx-loopback
  backends.update(_get_backends("networkx.backends"))
/lustre/fs24/group/cqta/atucci/environment2/lib64/python3.9/site-packages/networkx/utils/backends.py:135: RuntimeWarning: networkx backend defined more than once: nx-loopback
  backends.update(_get_backends("networkx.backends"))
/bin/bash: /afs/ifh.de/user/t/tuccia/.profile: Permission denied
Traceback (most recent call last):
  File "/lustre/fs24/group/cqta/atucci/Random_cubo/codes/run_qubo_shots.py", line 190, in <module>
    main()
  File "/lustre/fs24/group/cqta/atucci/Random_cubo/codes/run_qubo_shots.py", line 74, in main
    with open(instance_dir + '/QUBO_' + str(n_qubits ) + 'V_'+ 'r_'+ str(r)+ '.gpickle', 'rb') as f:
FileNotFoundError: [Errno 2] No such file or directory: '../instances/0.95/N_22/QUBO_22V_r_399.gpickle'
/lustre/fs24/group/cqta/atucci/environment2/lib64/python3.9/site-packages/networkx/utils/backends.py:135: RuntimeWarning: networkx backend defined more than once: nx-loopback
  backends.update(_get_backends("networkx.backends"))
/bin/bash: /afs/ifh.de/user/t/tuccia/.profile: Permission denied
/bin/bash: /afs/ifh.de/user/t/tuccia/.profile: Permission denied
Traceback (most recent call last):
  File "/lustre/fs24/group/cqta/atucci/Random_cubo/codes/run_qubo_shots.py", line 190, in <module>
    main()
  File "/lustre/fs24/group/cqta/atucci/Random_cubo/codes/run_qubo_shots.py", line 74, in main
    with open(instance_dir + '/QUBO_' + str(n_qubits ) + 'V_'+ 'r_'+ str(r)+ '.gpickle', 'rb') as f:
FileNotFoundError: [Errno 2] No such file or directory: '../instances/0.9/N_22/QUBO_22V_r_395.gpickle'
/lustre/fs24/group/cqta/atucci/environment2/lib64/python3.9/site-packages/networkx/utils/backends.py:135: RuntimeWarning: networkx backend defined more than once: nx-loopback
  backends.update(_get_backends("networkx.backends"))
/lustre/fs24/group/cqta/atucci/environment2/lib64/python3.9/site-packages/networkx/utils/backends.py:135: RuntimeWarning: networkx backend defined more than once: nx-loopback
  backends.update(_get_backends("networkx.backends"))
Traceback (most recent call last):
  File "/lustre/fs24/group/cqta/atucci/Random_cubo/codes/run_qubo_shots.py", line 190, in <module>
    main()
  File "/lustre/fs24/group/cqta/atucci/Random_cubo/codes/run_qubo_shots.py", line 74, in main
    with open(instance_dir + '/QUBO_' + str(n_qubits ) + 'V_'+ 'r_'+ str(r)+ '.gpickle', 'rb') as f:
FileNotFoundError: [Errno 2] No such file or directory: '../instances/0.95/N_22/QUBO_22V_r_390.gpickle'
/bin/bash: /afs/ifh.de/user/t/tuccia/.profile: Permission denied
Traceback (most recent call last):
  File "/lustre/fs24/group/cqta/atucci/Random_cubo/codes/run_qubo_shots.py", line 190, in <module>
    main()
  File "/lustre/fs24/group/cqta/atucci/Random_cubo/codes/run_qubo_shots.py", line 74, in main
    with open(instance_dir + '/QUBO_' + str(n_qubits ) + 'V_'+ 'r_'+ str(r)+ '.gpickle', 'rb') as f:
FileNotFoundError: [Errno 2] No such file or directory: '../instances/0.9/N_22/QUBO_22V_r_344.gpickle'
/lustre/fs24/group/cqta/atucci/environment2/lib64/python3.9/site-packages/networkx/utils/backends.py:135: RuntimeWarning: networkx backend defined more than once: nx-loopback
  backends.update(_get_backends("networkx.backends"))
/bin/bash: /afs/ifh.de/user/t/tuccia/.profile: Permission denied
/lustre/fs24/group/cqta/atucci/environment2/lib64/python3.9/site-packages/networkx/utils/backends.py:135: RuntimeWarning: networkx backend defined more than once: nx-loopback
  backends.update(_get_backends("networkx.backends"))
/bin/bash: /afs/ifh.de/user/t/tuccia/.profile: Permission denied
Traceback (most recent call last):
  File "/lustre/fs24/group/cqta/atucci/Random_cubo/codes/run_qubo_shots.py", line 190, in <module>
    main()
  File "/lustre/fs24/group/cqta/atucci/Random_cubo/codes/run_qubo_shots.py", line 74, in main
    with open(instance_dir + '/QUBO_' + str(n_qubits ) + 'V_'+ 'r_'+ str(r)+ '.gpickle', 'rb') as f:
FileNotFoundError: [Errno 2] No such file or directory: '../instances/0.95/N_22/QUBO_22V_r_397.gpickle'
/lustre/fs24/group/cqta/atucci/environment2/lib64/python3.9/site-packages/networkx/utils/backends.py:135: RuntimeWarning: networkx backend defined more than once: nx-loopback
  backends.update(_get_backends("networkx.backends"))
Traceback (most recent call last):
  File "/lustre/fs24/group/cqta/atucci/Random_cubo/codes/run_qubo_shots.py", line 190, in <module>
    main()
  File "/lustre/fs24/group/cqta/atucci/Random_cubo/codes/run_qubo_shots.py", line 74, in main
    with open(instance_dir + '/QUBO_' + str(n_qubits ) + 'V_'+ 'r_'+ str(r)+ '.gpickle', 'rb') as f:
FileNotFoundError: [Errno 2] No such file or directory: '../instances/0.9/N_22/QUBO_22V_r_312.gpickle'
/bin/bash: /afs/ifh.de/user/t/tuccia/.profile: Permission denied
/lustre/fs24/group/cqta/atucci/environment2/lib64/python3.9/site-packages/networkx/utils/backends.py:135: RuntimeWarning: networkx backend defined more than once: nx-loopback
  backends.update(_get_backends("networkx.backends"))
/bin/bash: /afs/ifh.de/user/t/tuccia/.profile: Permission denied
Traceback (most recent call last):
  File "/lustre/fs24/group/cqta/atucci/Random_cubo/codes/run_qubo_shots.py", line 190, in <module>
    main()
  File "/lustre/fs24/group/cqta/atucci/Random_cubo/codes/run_qubo_shots.py", line 74, in main
    with open(instance_dir + '/QUBO_' + str(n_qubits ) + 'V_'+ 'r_'+ str(r)+ '.gpickle', 'rb') as f:
FileNotFoundError: [Errno 2] No such file or directory: '../instances/0.95/N_22/QUBO_22V_r_364.gpickle'
Traceback (most recent call last):
  File "/lustre/fs24/group/cqta/atucci/Random_cubo/codes/run_qubo_shots.py", line 190, in <module>
    main()
  File "/lustre/fs24/group/cqta/atucci/Random_cubo/codes/run_qubo_shots.py", line 74, in main
    with open(instance_dir + '/QUBO_' + str(n_qubits ) + 'V_'+ 'r_'+ str(r)+ '.gpickle', 'rb') as f:
FileNotFoundError: [Errno 2] No such file or directory: '../instances/0.9/N_22/QUBO_22V_r_394.gpickle'
/lustre/fs24/group/cqta/atucci/environment2/lib64/python3.9/site-packages/networkx/utils/backends.py:135: RuntimeWarning: networkx backend defined more than once: nx-loopback
  backends.update(_get_backends("networkx.backends"))
/bin/bash: /afs/ifh.de/user/t/tuccia/.profile: Permission denied
/lustre/fs24/group/cqta/atucci/environment2/lib64/python3.9/site-packages/networkx/utils/backends.py:135: RuntimeWarning: networkx backend defined more than once: nx-loopback
  backends.update(_get_backends("networkx.backends"))
/bin/bash: /afs/ifh.de/user/t/tuccia/.profile: Permission denied
/lustre/fs24/group/cqta/atucci/environment2/lib64/python3.9/site-packages/networkx/utils/backends.py:135: RuntimeWarning: networkx backend defined more than once: nx-loopback
  backends.update(_get_backends("networkx.backends"))
/bin/bash: /afs/ifh.de/user/t/tuccia/.profile: Permission denied
/lustre/fs24/group/cqta/atucci/environment2/lib64/python3.9/site-packages/networkx/utils/backends.py:135: RuntimeWarning: networkx backend defined more than once: nx-loopback
  backends.update(_get_backends("networkx.backends"))
Traceback (most recent call last):
  File "/lustre/fs24/group/cqta/atucci/Random_cubo/codes/run_qubo_shots.py", line 190, in <module>
    main()
  File "/lustre/fs24/group/cqta/atucci/Random_cubo/codes/run_qubo_shots.py", line 74, in main
    with open(instance_dir + '/QUBO_' + str(n_qubits ) + 'V_'+ 'r_'+ str(r)+ '.gpickle', 'rb') as f:
FileNotFoundError: [Errno 2] No such file or directory: '../instances/0.9/N_22/QUBO_22V_r_351.gpickle'
/bin/bash: /afs/ifh.de/user/t/tuccia/.profile: Permission denied
/lustre/fs24/group/cqta/atucci/environment2/lib64/python3.9/site-packages/networkx/utils/backends.py:135: RuntimeWarning: networkx backend defined more than once: nx-loopback
  backends.update(_get_backends("networkx.backends"))
Traceback (most recent call last):
  File "/lustre/fs24/group/cqta/atucci/Random_cubo/codes/run_qubo_shots.py", line 190, in <module>
    main()
  File "/lustre/fs24/group/cqta/atucci/Random_cubo/codes/run_qubo_shots.py", line 74, in main
    with open(instance_dir + '/QUBO_' + str(n_qubits ) + 'V_'+ 'r_'+ str(r)+ '.gpickle', 'rb') as f:
FileNotFoundError: [Errno 2] No such file or directory: '../instances/0.95/N_22/QUBO_22V_r_307.gpickle'
/bin/bash: /afs/ifh.de/user/t/tuccia/.profile: Permission denied
/lustre/fs24/group/cqta/atucci/environment2/lib64/python3.9/site-packages/networkx/utils/backends.py:135: RuntimeWarning: networkx backend defined more than once: nx-loopback
  backends.update(_get_backends("networkx.backends"))
/bin/bash: /afs/ifh.de/user/t/tuccia/.profile: Permission denied
/lustre/fs24/group/cqta/atucci/environment2/lib64/python3.9/site-packages/networkx/utils/backends.py:135: RuntimeWarning: networkx backend defined more than once: nx-loopback
  backends.update(_get_backends("networkx.backends"))
/bin/bash: /afs/ifh.de/user/t/tuccia/.profile: Permission denied
/lustre/fs24/group/cqta/atucci/environment2/lib64/python3.9/site-packages/networkx/utils/backends.py:135: RuntimeWarning: networkx backend defined more than once: nx-loopback
  backends.update(_get_backends("networkx.backends"))
Traceback (most recent call last):
  File "/lustre/fs24/group/cqta/atucci/Random_cubo/codes/run_qubo_shots.py", line 190, in <module>
    main()
  File "/lustre/fs24/group/cqta/atucci/Random_cubo/codes/run_qubo_shots.py", line 74, in main
    with open(instance_dir + '/QUBO_' + str(n_qubits ) + 'V_'+ 'r_'+ str(r)+ '.gpickle', 'rb') as f:
FileNotFoundError: [Errno 2] No such file or directory: '../instances/0.9/N_22/QUBO_22V_r_393.gpickle'
Traceback (most recent call last):
  File "/lustre/fs24/group/cqta/atucci/Random_cubo/codes/run_qubo_shots.py", line 190, in <module>
    main()
  File "/lustre/fs24/group/cqta/atucci/Random_cubo/codes/run_qubo_shots.py", line 74, in main
    with open(instance_dir + '/QUBO_' + str(n_qubits ) + 'V_'+ 'r_'+ str(r)+ '.gpickle', 'rb') as f:
FileNotFoundError: [Errno 2] No such file or directory: '../instances/0.95/N_22/QUBO_22V_r_380.gpickle'
/bin/bash: /afs/ifh.de/user/t/tuccia/.profile: Permission denied
/lustre/fs24/group/cqta/atucci/environment2/lib64/python3.9/site-packages/networkx/utils/backends.py:135: RuntimeWarning: networkx backend defined more than once: nx-loopback
  backends.update(_get_backends("networkx.backends"))
/bin/bash: /afs/ifh.de/user/t/tuccia/.profile: Permission denied
/lustre/fs24/group/cqta/atucci/environment2/lib64/python3.9/site-packages/networkx/utils/backends.py:135: RuntimeWarning: networkx backend defined more than once: nx-loopback
  backends.update(_get_backends("networkx.backends"))
Traceback (most recent call last):
  File "/lustre/fs24/group/cqta/atucci/Random_cubo/codes/run_qubo_shots.py", line 190, in <module>
    main()
  File "/lustre/fs24/group/cqta/atucci/Random_cubo/codes/run_qubo_shots.py", line 74, in main
    with open(instance_dir + '/QUBO_' + str(n_qubits ) + 'V_'+ 'r_'+ str(r)+ '.gpickle', 'rb') as f:
FileNotFoundError: [Errno 2] No such file or directory: '../instances/0.9/N_22/QUBO_22V_r_377.gpickle'
/bin/bash: /afs/ifh.de/user/t/tuccia/.profile: Permission denied
/lustre/fs24/group/cqta/atucci/environment2/lib64/python3.9/site-packages/networkx/utils/backends.py:135: RuntimeWarning: networkx backend defined more than once: nx-loopback
  backends.update(_get_backends("networkx.backends"))
/bin/bash: /afs/ifh.de/user/t/tuccia/.profile: Permission denied
Traceback (most recent call last):
  File "/lustre/fs24/group/cqta/atucci/Random_cubo/codes/run_qubo_shots.py", line 190, in <module>
    main()
  File "/lustre/fs24/group/cqta/atucci/Random_cubo/codes/run_qubo_shots.py", line 74, in main
    with open(instance_dir + '/QUBO_' + str(n_qubits ) + 'V_'+ 'r_'+ str(r)+ '.gpickle', 'rb') as f:
FileNotFoundError: [Errno 2] No such file or directory: '../instances/0.95/N_22/QUBO_22V_r_391.gpickle'
/lustre/fs24/group/cqta/atucci/environment2/lib64/python3.9/site-packages/networkx/utils/backends.py:135: RuntimeWarning: networkx backend defined more than once: nx-loopback
  backends.update(_get_backends("networkx.backends"))
Traceback (most recent call last):
  File "/lustre/fs24/group/cqta/atucci/Random_cubo/codes/run_qubo_shots.py", line 190, in <module>
    main()
  File "/lustre/fs24/group/cqta/atucci/Random_cubo/codes/run_qubo_shots.py", line 74, in main
    with open(instance_dir + '/QUBO_' + str(n_qubits ) + 'V_'+ 'r_'+ str(r)+ '.gpickle', 'rb') as f:
FileNotFoundError: [Errno 2] No such file or directory: '../instances/0.9/N_22/QUBO_22V_r_369.gpickle'
/bin/bash: /afs/ifh.de/user/t/tuccia/.profile: Permission denied
/lustre/fs24/group/cqta/atucci/environment2/lib64/python3.9/site-packages/networkx/utils/backends.py:135: RuntimeWarning: networkx backend defined more than once: nx-loopback
  backends.update(_get_backends("networkx.backends"))
Traceback (most recent call last):
  File "/lustre/fs24/group/cqta/atucci/Random_cubo/codes/run_qubo_shots.py", line 190, in <module>
    main()
  File "/lustre/fs24/group/cqta/atucci/Random_cubo/codes/run_qubo_shots.py", line 74, in main
    with open(instance_dir + '/QUBO_' + str(n_qubits ) + 'V_'+ 'r_'+ str(r)+ '.gpickle', 'rb') as f:
FileNotFoundError: [Errno 2] No such file or directory: '../instances/0.9/N_22/QUBO_22V_r_320.gpickle'
/bin/bash: /afs/ifh.de/user/t/tuccia/.profile: Permission denied
/lustre/fs24/group/cqta/atucci/environment2/lib64/python3.9/site-packages/networkx/utils/backends.py:135: RuntimeWarning: networkx backend defined more than once: nx-loopback
  backends.update(_get_backends("networkx.backends"))
/bin/bash: /afs/ifh.de/user/t/tuccia/.profile: Permission denied
/lustre/fs24/group/cqta/atucci/environment2/lib64/python3.9/site-packages/networkx/utils/backends.py:135: RuntimeWarning: networkx backend defined more than once: nx-loopback
  backends.update(_get_backends("networkx.backends"))
/bin/bash: /afs/ifh.de/user/t/tuccia/.profile: Permission denied
Traceback (most recent call last):
  File "/lustre/fs24/group/cqta/atucci/Random_cubo/codes/run_qubo_shots.py", line 190, in <module>
    main()
  File "/lustre/fs24/group/cqta/atucci/Random_cubo/codes/run_qubo_shots.py", line 74, in main
    with open(instance_dir + '/QUBO_' + str(n_qubits ) + 'V_'+ 'r_'+ str(r)+ '.gpickle', 'rb') as f:
FileNotFoundError: [Errno 2] No such file or directory: '../instances/0.9/N_22/QUBO_22V_r_392.gpickle'
/lustre/fs24/group/cqta/atucci/environment2/lib64/python3.9/site-packages/networkx/utils/backends.py:135: RuntimeWarning: networkx backend defined more than once: nx-loopback
  backends.update(_get_backends("networkx.backends"))
Traceback (most recent call last):
  File "/lustre/fs24/group/cqta/atucci/Random_cubo/codes/run_qubo_shots.py", line 190, in <module>
    main()
  File "/lustre/fs24/group/cqta/atucci/Random_cubo/codes/run_qubo_shots.py", line 74, in main
    with open(instance_dir + '/QUBO_' + str(n_qubits ) + 'V_'+ 'r_'+ str(r)+ '.gpickle', 'rb') as f:
FileNotFoundError: [Errno 2] No such file or directory: '../instances/0.95/N_22/QUBO_22V_r_313.gpickle'
/bin/bash: /afs/ifh.de/user/t/tuccia/.profile: Permission denied
/lustre/fs24/group/cqta/atucci/environment2/lib64/python3.9/site-packages/networkx/utils/backends.py:135: RuntimeWarning: networkx backend defined more than once: nx-loopback
  backends.update(_get_backends("networkx.backends"))
/bin/bash: /afs/ifh.de/user/t/tuccia/.profile: Permission denied
/lustre/fs24/group/cqta/atucci/environment2/lib64/python3.9/site-packages/networkx/utils/backends.py:135: RuntimeWarning: networkx backend defined more than once: nx-loopback
  backends.update(_get_backends("networkx.backends"))
/bin/bash: /afs/ifh.de/user/t/tuccia/.profile: Permission denied
/lustre/fs24/group/cqta/atucci/environment2/lib64/python3.9/site-packages/networkx/utils/backends.py:135: RuntimeWarning: networkx backend defined more than once: nx-loopback
  backends.update(_get_backends("networkx.backends"))
/bin/bash: /afs/ifh.de/user/t/tuccia/.profile: Permission denied
/lustre/fs24/group/cqta/atucci/environment2/lib64/python3.9/site-packages/networkx/utils/backends.py:135: RuntimeWarning: networkx backend defined more than once: nx-loopback
  backends.update(_get_backends("networkx.backends"))
Traceback (most recent call last):
  File "/lustre/fs24/group/cqta/atucci/Random_cubo/codes/run_qubo_shots.py", line 190, in <module>
    main()
  File "/lustre/fs24/group/cqta/atucci/Random_cubo/codes/run_qubo_shots.py", line 74, in main
    with open(instance_dir + '/QUBO_' + str(n_qubits ) + 'V_'+ 'r_'+ str(r)+ '.gpickle', 'rb') as f:
FileNotFoundError: [Errno 2] No such file or directory: '../instances/0.95/N_22/QUBO_22V_r_352.gpickle'
/bin/bash: /afs/ifh.de/user/t/tuccia/.profile: Permission denied
Traceback (most recent call last):
  File "/lustre/fs24/group/cqta/atucci/Random_cubo/codes/run_qubo_shots.py", line 190, in <module>
    main()
  File "/lustre/fs24/group/cqta/atucci/Random_cubo/codes/run_qubo_shots.py", line 74, in main
    with open(instance_dir + '/QUBO_' + str(n_qubits ) + 'V_'+ 'r_'+ str(r)+ '.gpickle', 'rb') as f:
FileNotFoundError: [Errno 2] No such file or directory: '../instances/0.95/N_22/QUBO_22V_r_361.gpickle'
/lustre/fs24/group/cqta/atucci/environment2/lib64/python3.9/site-packages/networkx/utils/backends.py:135: RuntimeWarning: networkx backend defined more than once: nx-loopback
  backends.update(_get_backends("networkx.backends"))
/bin/bash: /afs/ifh.de/user/t/tuccia/.profile: Permission denied
/lustre/fs24/group/cqta/atucci/environment2/lib64/python3.9/site-packages/networkx/utils/backends.py:135: RuntimeWarning: networkx backend defined more than once: nx-loopback
  backends.update(_get_backends("networkx.backends"))
Traceback (most recent call last):
  File "/lustre/fs24/group/cqta/atucci/Random_cubo/codes/run_qubo_shots.py", line 190, in <module>
    main()
  File "/lustre/fs24/group/cqta/atucci/Random_cubo/codes/run_qubo_shots.py", line 74, in main
    with open(instance_dir + '/QUBO_' + str(n_qubits ) + 'V_'+ 'r_'+ str(r)+ '.gpickle', 'rb') as f:
FileNotFoundError: [Errno 2] No such file or directory: '../instances/0.9/N_22/QUBO_22V_r_264.gpickle'
/bin/bash: /afs/ifh.de/user/t/tuccia/.profile: Permission denied
/lustre/fs24/group/cqta/atucci/environment2/lib64/python3.9/site-packages/networkx/utils/backends.py:135: RuntimeWarning: networkx backend defined more than once: nx-loopback
  backends.update(_get_backends("networkx.backends"))
Traceback (most recent call last):
  File "/lustre/fs24/group/cqta/atucci/Random_cubo/codes/run_qubo_shots.py", line 190, in <module>
    main()
  File "/lustre/fs24/group/cqta/atucci/Random_cubo/codes/run_qubo_shots.py", line 74, in main
    with open(instance_dir + '/QUBO_' + str(n_qubits ) + 'V_'+ 'r_'+ str(r)+ '.gpickle', 'rb') as f:
FileNotFoundError: [Errno 2] No such file or directory: '../instances/0.9/N_22/QUBO_22V_r_325.gpickle'
/bin/bash: /afs/ifh.de/user/t/tuccia/.profile: Permission denied
/lustre/fs24/group/cqta/atucci/environment2/lib64/python3.9/site-packages/networkx/utils/backends.py:135: RuntimeWarning: networkx backend defined more than once: nx-loopback
  backends.update(_get_backends("networkx.backends"))
/bin/bash: /afs/ifh.de/user/t/tuccia/.profile: Permission denied
/lustre/fs24/group/cqta/atucci/environment2/lib64/python3.9/site-packages/networkx/utils/backends.py:135: RuntimeWarning: networkx backend defined more than once: nx-loopback
  backends.update(_get_backends("networkx.backends"))
Traceback (most recent call last):
  File "/lustre/fs24/group/cqta/atucci/Random_cubo/codes/run_qubo_shots.py", line 190, in <module>
    main()
  File "/lustre/fs24/group/cqta/atucci/Random_cubo/codes/run_qubo_shots.py", line 74, in main
    with open(instance_dir + '/QUBO_' + str(n_qubits ) + 'V_'+ 'r_'+ str(r)+ '.gpickle', 'rb') as f:
FileNotFoundError: [Errno 2] No such file or directory: '../instances/0.9/N_22/QUBO_22V_r_360.gpickle'
Traceback (most recent call last):
  File "/lustre/fs24/group/cqta/atucci/Random_cubo/codes/run_qubo_shots.py", line 190, in <module>
    main()
  File "/lustre/fs24/group/cqta/atucci/Random_cubo/codes/run_qubo_shots.py", line 74, in main
    with open(instance_dir + '/QUBO_' + str(n_qubits ) + 'V_'+ 'r_'+ str(r)+ '.gpickle', 'rb') as f:
FileNotFoundError: [Errno 2] No such file or directory: '../instances/0.95/N_22/QUBO_22V_r_336.gpickle'
/bin/bash: /afs/ifh.de/user/t/tuccia/.profile: Permission denied
/lustre/fs24/group/cqta/atucci/environment2/lib64/python3.9/site-packages/networkx/utils/backends.py:135: RuntimeWarning: networkx backend defined more than once: nx-loopback
  backends.update(_get_backends("networkx.backends"))
/bin/bash: /afs/ifh.de/user/t/tuccia/.profile: Permission denied
/lustre/fs24/group/cqta/atucci/environment2/lib64/python3.9/site-packages/networkx/utils/backends.py:135: RuntimeWarning: networkx backend defined more than once: nx-loopback
  backends.update(_get_backends("networkx.backends"))
/bin/bash: /afs/ifh.de/user/t/tuccia/.profile: Permission denied
/lustre/fs24/group/cqta/atucci/environment2/lib64/python3.9/site-packages/networkx/utils/backends.py:135: RuntimeWarning: networkx backend defined more than once: nx-loopback
  backends.update(_get_backends("networkx.backends"))
/bin/bash: /afs/ifh.de/user/t/tuccia/.profile: Permission denied
/lustre/fs24/group/cqta/atucci/environment2/lib64/python3.9/site-packages/networkx/utils/backends.py:135: RuntimeWarning: networkx backend defined more than once: nx-loopback
  backends.update(_get_backends("networkx.backends"))
Traceback (most recent call last):
  File "/lustre/fs24/group/cqta/atucci/Random_cubo/codes/run_qubo_shots.py", line 190, in <module>
    main()
  File "/lustre/fs24/group/cqta/atucci/Random_cubo/codes/run_qubo_shots.py", line 74, in main
    with open(instance_dir + '/QUBO_' + str(n_qubits ) + 'V_'+ 'r_'+ str(r)+ '.gpickle', 'rb') as f:
FileNotFoundError: [Errno 2] No such file or directory: '../instances/0.95/N_22/QUBO_22V_r_396.gpickle'
/bin/bash: /afs/ifh.de/user/t/tuccia/.profile: Permission denied
/lustre/fs24/group/cqta/atucci/environment2/lib64/python3.9/site-packages/networkx/utils/backends.py:135: RuntimeWarning: networkx backend defined more than once: nx-loopback
  backends.update(_get_backends("networkx.backends"))
/bin/bash: /afs/ifh.de/user/t/tuccia/.profile: Permission denied
/lustre/fs24/group/cqta/atucci/environment2/lib64/python3.9/site-packages/networkx/utils/backends.py:135: RuntimeWarning: networkx backend defined more than once: nx-loopback
  backends.update(_get_backends("networkx.backends"))
Traceback (most recent call last):
  File "/lustre/fs24/group/cqta/atucci/Random_cubo/codes/run_qubo_shots.py", line 190, in <module>
    main()
  File "/lustre/fs24/group/cqta/atucci/Random_cubo/codes/run_qubo_shots.py", line 74, in main
    with open(instance_dir + '/QUBO_' + str(n_qubits ) + 'V_'+ 'r_'+ str(r)+ '.gpickle', 'rb') as f:
FileNotFoundError: [Errno 2] No such file or directory: '../instances/0.9/N_22/QUBO_22V_r_365.gpickle'
/bin/bash: /afs/ifh.de/user/t/tuccia/.profile: Permission denied
/lustre/fs24/group/cqta/atucci/environment2/lib64/python3.9/site-packages/networkx/utils/backends.py:135: RuntimeWarning: networkx backend defined more than once: nx-loopback
  backends.update(_get_backends("networkx.backends"))
/bin/bash: /afs/ifh.de/user/t/tuccia/.profile: Permission denied
/lustre/fs24/group/cqta/atucci/environment2/lib64/python3.9/site-packages/networkx/utils/backends.py:135: RuntimeWarning: networkx backend defined more than once: nx-loopback
  backends.update(_get_backends("networkx.backends"))
Traceback (most recent call last):
  File "/lustre/fs24/group/cqta/atucci/Random_cubo/codes/run_qubo_shots.py", line 190, in <module>
    main()
  File "/lustre/fs24/group/cqta/atucci/Random_cubo/codes/run_qubo_shots.py", line 74, in main
    with open(instance_dir + '/QUBO_' + str(n_qubits ) + 'V_'+ 'r_'+ str(r)+ '.gpickle', 'rb') as f:
FileNotFoundError: [Errno 2] No such file or directory: '../instances/0.95/N_22/QUBO_22V_r_282.gpickle'
/bin/bash: /afs/ifh.de/user/t/tuccia/.profile: Permission denied
/lustre/fs24/group/cqta/atucci/environment2/lib64/python3.9/site-packages/networkx/utils/backends.py:135: RuntimeWarning: networkx backend defined more than once: nx-loopback
  backends.update(_get_backends("networkx.backends"))
Traceback (most recent call last):
  File "/lustre/fs24/group/cqta/atucci/Random_cubo/codes/run_qubo_shots.py", line 190, in <module>
    main()
  File "/lustre/fs24/group/cqta/atucci/Random_cubo/codes/run_qubo_shots.py", line 74, in main
    with open(instance_dir + '/QUBO_' + str(n_qubits ) + 'V_'+ 'r_'+ str(r)+ '.gpickle', 'rb') as f:
FileNotFoundError: [Errno 2] No such file or directory: '../instances/0.9/N_22/QUBO_22V_r_370.gpickle'
Traceback (most recent call last):
  File "/lustre/fs24/group/cqta/atucci/Random_cubo/codes/run_qubo_shots.py", line 190, in <module>
    main()
  File "/lustre/fs24/group/cqta/atucci/Random_cubo/codes/run_qubo_shots.py", line 148, in main
    poss, exp_poss_dict, cvar, expz_array = compute_expectations(n_qubits, eigen_list, circ, shots, alpha)
  File "/lustre/fs24/group/cqta/atucci/Random_cubo/codes/../codes/functions.py", line 424, in compute_expectations
    cvar /= total_prob
ZeroDivisionError: float division by zero
Traceback (most recent call last):
  File "/lustre/fs24/group/cqta/atucci/Random_cubo/codes/run_qubo_shots.py", line 190, in <module>
    main()
  File "/lustre/fs24/group/cqta/atucci/Random_cubo/codes/run_qubo_shots.py", line 116, in main
    poss, exp_poss_dict, cvar, expz_array = compute_expectations(n_qubits, eigen_list, circ, shots, alpha)
  File "/lustre/fs24/group/cqta/atucci/Random_cubo/codes/../codes/functions.py", line 424, in compute_expectations
    cvar /= total_prob
ZeroDivisionError: float division by zero
